Workbook

Sheet Theory
A1: DAYANANDA SAGAR COLLEGE OF ENGINEERING, BANGALORE-560 111
A2: DEPARTMENT OF ARTIFICIAL INTELLEGENCE & MACHINE LEARNING
A4: Academic Year : 2024 -25 | D4: Scheme :2022-26 | Q4: Semester : 3rd
A5: COURSE CODE : 22AI33
A6: COURSE TITLE :DBMS
A7: STAND ALONE THEORY | D7: NO
A8: STAND ALONE LAB | D8: NO
A9: IPCC | D9: Yes
A10: Faculty : Anupama V P
C11: Course Outcome Attainment Calculation
C12: COs mapped | D12: 0,1 | H12: 0,4 | L12: 0,2 | P12: 0,2 | T12: 0,1 | X12: 0,1 | AB12: 0,4 | AF12: 0,4 | AJ12: 0,4 | AN12: 0,3 | AR12: 0,4 | AV12: 0,4 | AZ12: 0,4 | BD12: 0,4 | BH12: 0,3 | BL12: 0,3 | BP12: 0,3 | BT12: 0,5 | BX12: 0,3 | CB12: 0,3 | CF12: 0,5 | CJ12: 0,5 | CN12: 0,5 | CR12: 0,5 | CV12: 0,1,2,3,4,5,6 | CW12: 0,1,2,3,4,5,6 | DK12: ENTER ATTENDANCE MANUALLY FOR CSV FILE
D13: Test 1 | AJ13: Test 2 | BP13: Test 3 | CV13: AAT | CW13: QUIZ | DK13: STAND ALONE THEORY ATTENDANCE | DL13: STAND ALONE THEORY ATTENDANCE | DM13: STAND ALONE THEORY ATTENDANCE | DN13: STAND ALONE THEORY ATTENDANCE | DO13: STAND ALONE LAB ATTENDANCE | DP13: IPCC THEORY ATTENDANCE | DQ13: IPCC LAB ATTENDANCE | DR13: IPCC TOTAL ATTENDANCE
C14: Maximum Marks | D14: 10 | H14: 10 | L14: 10 | P14: 10 | T14: 10 | X14: 10 | AB14: 10 | AF14: 10 | AJ14: 10 | AN14: 10 | AR14: 10 | AV14: 10 | AZ14: 10 | BD14: 10 | BH14: 10 | BL14: 10 | BP14: 10 | BT14: 10 | BX14: 10 | CB14: 10 | CF14: 10 | CJ14: 10 | CN14: 10 | CR14: 10 | CV14: 10 | CW14: 10 | CX14: 50 | CY14: 50 | CZ14: 50 | DA14: 50 | DB14: 50 | DC14: 100 | DF14: CIA | DI14: SEE | DK14: CREDIT-1 | DL14: CREDIT-2 | DM14: CREDIT-3 | DN14: CREDIT-4 | DO14: CREDIT-1 | DP14: CREDIT-4
C15: Marks to reach Performance (60% and above of Max. Marks) | D15: =PRODUCT(D14,0.6) -> 6 | E15: =PRODUCT(E14,0.6) -> 0.6 | H15: =PRODUCT(H14,0.6) -> 6 | I15: =PRODUCT(I14,0.6) -> 0.6 | L15: =PRODUCT(L14,0.6) -> 6 | M15: =PRODUCT(M14,0.6) -> 0.6 | P15: =PRODUCT(P14,0.6) -> 6 | Q15: =PRODUCT(Q14,0.6) -> 0.6 | T15: =PRODUCT(T14,0.6) -> 6 | X15: =PRODUCT(X14,0.6) -> 6 | AB15: =PRODUCT(AB14,0.6) -> 6 | AF15: =PRODUCT(AF14,0.6) -> 6 | AJ15: =PRODUCT(AJ14,0.6) -> 6 | AK15: =PRODUCT(AK14,0.6) -> 0.6 | AN15: =PRODUCT(AN14,0.6) -> 6 | AO15: =PRODUCT(AO14,0.6) -> 0.6 | AR15: =PRODUCT(AR14,0.6) -> 6 | AV15: =PRODUCT(AV14,0.6) -> 6 | AZ15: =PRODUCT(AZ14,0.6) -> 6 | BD15: =PRODUCT(BD14,0.6) -> 6 | BH15: =PRODUCT(BH14,0.6) -> 6 | BL15: =PRODUCT(BL14,0.6) -> 6 | BP15: =PRODUCT(BP14,0.6) -> 6 | BQ15: =PRODUCT(BQ14,0.6) -> 0.6 | BT15: =PRODUCT(BT14,0.6) -> 6 | BU15: =PRODUCT(BU14,0.6) -> 0.6 | BX15: =PRODUCT(BX14,0.6) -> 6 | CB15: =PRODUCT(CB14,0.6) -> 6 | CF15: =PRODUCT(CF14,0.6) -> 6 | CJ15: =PRODUCT(CJ14,0.6) -> 6 | CN15: =PRODUCT(CN14,0.6) -> 6 | CR15: =PRODUCT(CR14,0.6) -> 6 | CV15: =PRODUCT(CV14,0.6) -> 6 | CW15: =PRODUCT(CW14,0.6) -> 6 | CX15: =PRODUCT(CX14,0.6) -> 30 | CY15: =PRODUCT(CY14,0.6) -> 30 | CZ15: =PRODUCT(CZ14,0.6) -> 30 | DA15: =PRODUCT(DA14,0.6) -> 30 | DB15: =PRODUCT(DB14,0.6) -> 30 | DC15: 60 | DF15: ='CIA MARKS'!DX12 -> STAND ALONE THEORY | DG15: ='CIA MARKS'!EH12 -> STAND ALONE LAB | DH15: ='CIA MARKS'!EJ12 -> IPCC | DI15: ='CIA MARKS'!EK12 -> SEE | DK15: ATTND (11/12) | DL15: ATTND (11/24) | DM15: ATTND (34/40) | DN15: ATTND (45/52) | DO15: ATTND (11/12) | DP15: ATT-THEORY (34/40) | DQ15: ATT-LAB (11/12)
A16: Sl No. | B16: USN | C16: STUDENT NAME | D16: Q1A | E16: Q1B | F16: Q1C | G16: Q1D | H16: Q2A | I16: Q2B | J16: Q2C | K16: Q2D | L16: Q3A | M16: Q3B | N16: Q3C | O16: Q3D | P16: Q4A | Q16: Q4B | R16: Q4C | S16: Q4D | T16: Q5A | U16: Q5B | V16: Q5C | W16: Q5D | X16: Q6A | Y16: Q6B | Z16: Q6C | AA16: Q6D | AB16: Q7A | AC16: Q7B | AD16: Q7C | AE16: Q7D | AF16: Q8A | AG16: Q8B | AH16: Q8C | AI16: Q8D | AJ16: Q1A | AK16: Q1A | AL16: Q1C | AM16: Q1D | AN16: Q2A | AO16: Q2A | AP16: Q2C | AQ16: Q2D | AR16: Q3A | AS16: Q3B | AT16: Q3C | AU16: Q3D | AV16: Q4A | AW16: Q4B | AX16: Q4C | AY16: Q4D | AZ16: Q5A | BA16: Q5B | BB16: Q5C | BC16: Q5D | BD16: Q6A | BE16: Q6B | BF16: Q6C | BG16: Q6D | BH16: Q7A | BI16: Q7B | BJ16: Q7C | BK16: Q7D | BL16: Q8A | BM16: Q8B | BN16: Q8C | BO16: Q8D | BP16: Q1A | BQ16: Q1B | BR16: Q1C | BS16: Q1D | BT16: Q2A | BU16: Q2B | BV16: Q2C | BW16: Q2D | BX16: Q3A | BY16: Q3B | BZ16: Q3C | CA16: Q3D | CB16: Q4A | CC16: Q4B | CD16: Q4C | CE16: Q4D | CF16: Q5A | CG16: Q5B | CH16: Q5C | CI16: Q5D | CJ16: Q6A | CK16: Q6B | CL16: Q6C | CM16: Q6D | CN16: Q7A | CO16: Q7B | CP16: Q7C | CQ16: Q7D | CR16: Q8A | CS16: Q8B | CT16: Q8C | CU16: Q8D | CV16: Q1-20 | CW16: Q1-20 | CX16: Total Test1 | CY16: Total Test 2 | CZ16: Total Test 3 | DA16: Final CIA | DB16: Final SEE MARKS | DC16: Final SEE MARKS | DD16: Final SEE Grade | DF16: ='CIA MARKS'!DX13 -> 50 | DG16: ='CIA MARKS'!EH13 -> 50 | DH16: ='CIA MARKS'!EJ13 -> 50 | DI16: ='CIA MARKS'!EK13 -> 50 | DK16: 12 | DL16: 24 | DM16: 40 | DN16: 52 | DO16: 12 | DP16: 40 | DQ16: 12 | DR16: =SUM(DP16:DQ16) -> 52
A17: 1 | B17: 1DS23AI001 | C17: AAYUSH PANDEY | D17: 7 | H17: 4 | L17: 5 | T17: 4 | AB17: 9 | AJ17: 5 | AN17: 4 | AV17: 8 | BH17: 2 | BP17: 8 | BT17: 8 | BX17: 9 | CJ17: 9 | CR17: 3 | CV17: 7 | CW17: 10 | CX17: =VLOOKUP(B17,'CIA MARKS'!C14:DN83,116,FALSE) -> 29 | CY17: =VLOOKUP(B17,'CIA MARKS'!C14:DO83,117,FALSE) -> 19 | CZ17: =VLOOKUP(B17,'CIA MARKS'!C14:DP83,118,FALSE) -> 37 | DA17: ='CIA MARKS'!EJ14 -> 35 | DB17: =DC17/2 -> 38 | DC17: 76 | DD17: A | DF17: =IF(D$7="YES",'CIA MARKS'!DX14,"") | DG17: =IF(D$8="YES",'CIA MARKS'!EH14,"") | DH17: =IF(D$9="YES",'CIA MARKS'!EJ14,"") -> 35 | DI17: {=IF(D$8="YES",Lab!K9:K78,Theory!DB17:DB86)} -> 38 | DR17: =SUM(DP17:DQ17) -> 0
A18: 2 | B18: 1DS23AI002 | C18: ABHINAND PRAMEESH | D18: 10 | H18: 5 | L18: 8 | X18: 10 | AJ18: 2 | AN18: 6 | AV18: 8 | BD18: 2 | BL18: 4 | BP18: 9 | BT18: 9 | BX18: 10 | CF18: 9 | CN18: 10 | CV18: 6 | CW18: 10 | CX18: =VLOOKUP(B18,'CIA MARKS'!C15:DN84,116,FALSE) -> 33 | CY18: =VLOOKUP(B18,'CIA MARKS'!C15:DO84,117,FALSE) -> 22 | CZ18: =VLOOKUP(B18,'CIA MARKS'!C15:DP84,118,FALSE) -> 47 | DA18: ='CIA MARKS'!EJ15 -> 42 | DB18: =DC18/2 -> 38.5 | DC18: 77 | DD18: A+ | DF18: =IF(D$7="YES",'CIA MARKS'!DX15,"") | DG18: =IF(D$8="YES",'CIA MARKS'!EH15,"") | DH18: =IF(D$9="YES",'CIA MARKS'!EJ15,"") -> 42 | DI18: 38.5 | DR18: =SUM(DP18:DQ18) -> 0
A19: 3 | B19: 1DS23AI003 | C19: ABHISHEK SINGH | H19: 5 | L19: 5 | T19: 6 | AB19: 7 | AJ19: 8 | AN19: 9 | AV19: 9 | AZ19: 10 | BP19: 8 | BT19: 4 | CB19: 8 | CN19: 5 | CV19: 6 | CW19: 10 | CX19: =VLOOKUP(B19,'CIA MARKS'!C16:DN85,116,FALSE) -> 23 | CY19: =VLOOKUP(B19,'CIA MARKS'!C16:DO85,117,FALSE) -> 36 | CZ19: =VLOOKUP(B19,'CIA MARKS'!C16:DP85,118,FALSE) -> 25 | DA19: ='CIA MARKS'!EJ16 -> 34 | DB19: =DC19/2 -> 30 | DC19: 60 | DD19: B+ | DF19: =IF(D$7="YES",'CIA MARKS'!DX16,"") | DG19: =IF(D$8="YES",'CIA MARKS'!EH16,"") | DH19: =IF(D$9="YES",'CIA MARKS'!EJ16,"") -> 34 | DI19: 30 | DR19: =SUM(DP19:DQ19) -> 0
A20: 4 | B20: 1DS23AI004 | C20: ABHISHEK V | D20: 7 | H20: 8 | L20: 6 | T20: 7 | AF20: 10 | AJ20: 4 | AN20: 7 | AV20: 8 | AZ20: 4 | BH20: 5 | BP20: 5 | BT20: 8 | CB20: 1 | CF20: 5 | CV20: 8 | CW20: 10 | CX20: =VLOOKUP(B20,'CIA MARKS'!C17:DN86,116,FALSE) -> 38 | CY20: =VLOOKUP(B20,'CIA MARKS'!C17:DO86,117,FALSE) -> 28 | CZ20: =VLOOKUP(B20,'CIA MARKS'!C17:DP86,118,FALSE) -> 19 | DA20: ='CIA MARKS'!EJ17 -> 38 | DB20: =DC20/2 -> 32.5 | DC20: 65 | DD20: A | DF20: =IF(D$7="YES",'CIA MARKS'!DX17,"") | DG20: =IF(D$8="YES",'CIA MARKS'!EH17,"") | DH20: =IF(D$9="YES",'CIA MARKS'!EJ17,"") -> 38 | DI20: 32.5 | DR20: =SUM(DP20:DQ20) -> 0
A21: 5 | B21: 1DS23AI005 | C21: ADITYA B RAWANAWAR | D21: 7 | H21: 6 | L21: 5 | X21: 10 | AF21: 8 | AJ21: 8 | AN21: 6 | AR21: 6 | AZ21: 6 | BH21: 8 | BP21: 8 | BT21: 8 | CB21: 8 | CF21: 7 | CN21: 8 | CV21: 7 | CW21: 10 | CX21: =VLOOKUP(B21,'CIA MARKS'!C18:DN86,116,FALSE) -> 36 | CY21: 39 | CZ21: =VLOOKUP(B21,'CIA MARKS'!C18:DP86,118,FALSE) -> 39 | DA21: ='CIA MARKS'!EJ18 -> 41 | DB21: =DC21/2 -> 45.5 | DC21: 91 | DD21: A+ | DF21: =IF(D$7="YES",'CIA MARKS'!DX18,"") | DG21: =IF(D$8="YES",'CIA MARKS'!EH18,"") | DH21: =IF(D$9="YES",'CIA MARKS'!EJ18,"") -> 41 | DI21: 45.5 | DR21: =SUM(DP21:DQ21) -> 0
A22: 6 | B22: 1DS23AI006 | C22: ADITYA MUTHUSAMY A | D22: 1 | H22: 4 | L22: 8 | X22: 0 | AF22: 4 | AJ22: 2 | AV22: 5 | BD22: 3 | BL22: 3 | BP22: 2 | BT22: 2 | CB22: 7 | CF22: 6 | CN22: 5 | CV22: 5 | CW22: 10 | CX22: =VLOOKUP(B22,'CIA MARKS'!C19:DN87,116,FALSE) -> 17 | CY22: =VLOOKUP(B22,'CIA MARKS'!C19:DO87,117,FALSE) -> 13 | CZ22: =VLOOKUP(B22,'CIA MARKS'!C19:DP87,118,FALSE) -> 22 | DA22: ='CIA MARKS'!EJ19 -> 28 | DB22: =DC22/2 -> 26.5 | DC22: 53 | DD22: B | DF22: =IF(D$7="YES",'CIA MARKS'!DX19,"") | DG22: =IF(D$8="YES",'CIA MARKS'!EH19,"") | DH22: =IF(D$9="YES",'CIA MARKS'!EJ19,"") -> 28 | DI22: 26.5 | DR22: =SUM(DP22:DQ22) -> 0
A23: 7 | B23: 1DS23AI007 | C23: ADNAN SAMEER ANEKATTI | H23: 3 | L23: 3 | AF23: 3 | AN23: 4 | AV23: 6 | BH23: 0 | BP23: 6 | BT23: 8 | BX23: 9 | CF23: 10 | CN23: 6 | CV23: 8 | CW23: 10 | CX23: =VLOOKUP(B23,'CIA MARKS'!C20:DN88,116,FALSE) -> 9 | CY23: =VLOOKUP(B23,'CIA MARKS'!C20:DO88,117,FALSE) -> 10 | CZ23: =VLOOKUP(B23,'CIA MARKS'!C20:DP88,118,FALSE) -> 39 | DA23: ='CIA MARKS'!EJ20 -> 30 | DB23: =DC23/2 -> 28.5 | DC23: 57 | DD23: B | DF23: =IF(D$7="YES",'CIA MARKS'!DX20,"") | DG23: =IF(D$8="YES",'CIA MARKS'!EH20,"") | DH23: =IF(D$9="YES",'CIA MARKS'!EJ20,"") -> 30 | DI23: 28.5 | DR23: =SUM(DP23:DQ23) -> 0
A24: 8 | B24: 1DS23AI008 | C24: AKSHADHA SINGH | D24: 6 | H24: 3 | L24: 4 | T24: 8 | AB24: 0 | AN24: 4 | AR24: 4 | BP24: 2 | BT24: 3 | BX24: 4 | CF24: 7 | CR24: 4 | CV24: 7 | CW24: 10 | CX24: =VLOOKUP(B24,'CIA MARKS'!C21:DN89,116,FALSE) -> 21 | CY24: =VLOOKUP(B24,'CIA MARKS'!C21:DO89,117,FALSE) -> 8 | CZ24: =VLOOKUP(B24,'CIA MARKS'!C21:DP89,118,FALSE) -> 20 | DA24: ='CIA MARKS'!EJ21 -> 29 | DB24: =DC24/2 -> 30.5 | DC24: 61 | DD24: B+ | DF24: =IF(D$7="YES",'CIA MARKS'!DX21,"") | DG24: =IF(D$8="YES",'CIA MARKS'!EH21,"") | DH24: =IF(D$9="YES",'CIA MARKS'!EJ21,"") -> 29 | DI24: 30.5 | DR24: =SUM(DP24:DQ24) -> 0
A25: 9 | B25: 1DS23AI010 | C25: ANIMESH UPADHYAY | L25: 4 | AF25: 3 | AJ25: 4 | AN25: 0 | AV25: 2 | BD25: 0 | BL25: 0 | BT25: 8 | CB25: 8 | CF25: 6 | CV25: 5 | CW25: 5 | CX25: =VLOOKUP(B25,'CIA MARKS'!C22:DN90,116,FALSE) -> 7 | CY25: =VLOOKUP(B25,'CIA MARKS'!C22:DO90,117,FALSE) -> 6 | CZ25: =VLOOKUP(B25,'CIA MARKS'!C22:DP90,118,FALSE) -> 22 | DA25: ='CIA MARKS'!EJ22 -> 23 | DB25: =DC25/2 -> 20.5 | DC25: 41 | DD25: P | DF25: =IF(D$7="YES",'CIA MARKS'!DX22,"") | DG25: =IF(D$8="YES",'CIA MARKS'!EH22,"") | DH25: =IF(D$9="YES",'CIA MARKS'!EJ22,"") -> 23 | DI25: 20.5 | DR25: =SUM(DP25:DQ25) -> 0
A26: 10 | B26: 1DS23AI011 | C26: ASHWINI GANESH RATOD | D26: 9 | H26: 4 | L26: 6 | X26: 3 | AF26: 4 | AJ26: 2 | AN26: 6 | AV26: 8 | AZ26: 3 | BH26: 7 | BP26: 9 | BT26: 9 | BX26: 9 | CF26: 8 | CN26: 9 | CV26: 7 | CW26: 10 | CX26: =VLOOKUP(B26,'CIA MARKS'!C23:DN91,116,FALSE) -> 26 | CY26: =VLOOKUP(B26,'CIA MARKS'!C23:DO91,117,FALSE) -> 26 | CZ26: =VLOOKUP(B26,'CIA MARKS'!C23:DP91,118,FALSE) -> 44 | DA26: ='CIA MARKS'!EJ23 -> 39 | DB26: =DC26/2 -> 41 | DC26: 82 | DD26: A+ | DF26: =IF(D$7="YES",'CIA MARKS'!DX23,"") | DG26: =IF(D$8="YES",'CIA MARKS'!EH23,"") | DH26: =IF(D$9="YES",'CIA MARKS'!EJ23,"") -> 39 | DI26: 41 | DR26: =SUM(DP26:DQ26) -> 0
A27: 11 | B27: 1DS23AI012 | C27: AVIDUTT PUROHIT | D27: 9 | H27: 8 | L27: 6 | X27: 8 | AB27: 9 | AJ27: 8 | AN27: 6 | AV27: 9 | BD27: 2 | BL27: 6 | BP27: 8 | BT27: 7 | BX27: 7 | CF27: 8 | CN27: 3 | CV27: 8 | CW27: 10 | CX27: =VLOOKUP(B27,'CIA MARKS'!C24:DN92,116,FALSE) -> 40 | CY27: =VLOOKUP(B27,'CIA MARKS'!C24:DO92,117,FALSE) -> 31 | CZ27: =VLOOKUP(B27,'CIA MARKS'!C24:DP92,118,FALSE) -> 33 | DA27: ='CIA MARKS'!EJ24 -> 37 | DB27: =DC27/2 -> 32.5 | DC27: 65 | DD27: A | DF27: =IF(D$7="YES",'CIA MARKS'!DX24,"") | DG27: =IF(D$8="YES",'CIA MARKS'!EH24,"") | DH27: =IF(D$9="YES",'CIA MARKS'!EJ24,"") -> 37 | DI27: 32.5 | DR27: =SUM(DP27:DQ27) -> 0
A28: 12 | B28: 1DS23AI013 | C28: B N SHARATH | D28: 8 | H28: 4 | L28: 4 | X28: 10 | AF28: 4 | AJ28: 4 | AN28: 8 | AV28: 8 | AZ28: 9 | BH28: 8 | BP28: 7 | BT28: 8 | BX28: 7 | CF28: 8 | CN28: 9 | CV28: 9 | CW28: 10 | CX28: =VLOOKUP(B28,'CIA MARKS'!C25:DN93,116,FALSE) -> 30 | CY28: =VLOOKUP(B28,'CIA MARKS'!C25:DO93,117,FALSE) -> 37 | CZ28: =VLOOKUP(B28,'CIA MARKS'!C25:DP93,118,FALSE) -> 39 | DA28: ='CIA MARKS'!EJ25 -> 42 | DB28: =DC28/2 -> 43 | DC28: 86 | DD28: A+ | DF28: =IF(D$7="YES",'CIA MARKS'!DX25,"") | DG28: =IF(D$8="YES",'CIA MARKS'!EH25,"") | DH28: =IF(D$9="YES",'CIA MARKS'!EJ25,"") -> 42 | DI28: 43 | DR28: =SUM(DP28:DQ28) -> 0
A29: 13 | B29: 1DS23AI014 | C29: BANNURU NIKHIL TEJ | D29: 9 | H29: 8 | L29: 6 | T29: 8 | AF29: 9 | AJ29: 9 | AN29: 8 | AV29: 10 | BD29: 0 | BL29: 8 | BP29: 9 | BT29: 10 | CB29: 10 | CF29: 10 | CR29: 9 | CV29: 7 | CW29: 10 | CX29: =VLOOKUP(B29,'CIA MARKS'!C26:DN94,116,FALSE) -> 40 | CY29: =VLOOKUP(B29,'CIA MARKS'!C26:DO94,117,FALSE) -> 35 | CZ29: =VLOOKUP(B29,'CIA MARKS'!C26:DP94,118,FALSE) -> 48 | DA29: ='CIA MARKS'!EJ26 -> 43 | DB29: =DC29/2 -> 46 | DC29: 92 | DD29: A+ | DF29: =IF(D$7="YES",'CIA MARKS'!DX26,"") | DG29: =IF(D$8="YES",'CIA MARKS'!EH26,"") | DH29: =IF(D$9="YES",'CIA MARKS'!EJ26,"") -> 43 | DI29: 46 | DR29: =SUM(DP29:DQ29) -> 0
A30: 14 | B30: 1DS23AI015 | C30: BHOOMIKA RAJESH HEGDE | D30: 8 | H30: 9 | P30: 9 | X30: 10 | AF30: 8 | AJ30: 10 | AN30: 9 | AV30: 10 | AZ30: 8 | BH30: 10 | BP30: 10 | BT30: 10 | BX30: 9 | CF30: 10 | CR30: 6 | CV30: 8 | CW30: 10 | CX30: =VLOOKUP(B30,'CIA MARKS'!C27:DN95,116,FALSE) -> 44 | CY30: =VLOOKUP(B30,'CIA MARKS'!C27:DO95,117,FALSE) -> 47 | CZ30: =VLOOKUP(B30,'CIA MARKS'!C27:DP95,118,FALSE) -> 45 | DA30: ='CIA MARKS'!EJ27 -> 46 | DB30: =DC30/2 -> 44 | DC30: 88 | DD30: O | DF30: =IF(D$7="YES",'CIA MARKS'!DX27,"") | DG30: =IF(D$8="YES",'CIA MARKS'!EH27,"") | DH30: =IF(D$9="YES",'CIA MARKS'!EJ27,"") -> 46 | DI30: 44 | DR30: =SUM(DP30:DQ30) -> 0
A31: 15 | B31: 1DS23AI016 | C31: BRIJESH NIRANJAN K | D31: 10 | H31: 8 | L31: 7 | T31: 8 | AF31: 10 | AJ31: 6 | AN31: 10 | AV31: 10 | BD31: 8 | BL31: 6 | BP31: 10 | BT31: 10 | BX31: 10 | CF31: 7 | CN31: 8 | CV31: 7 | CW31: 10 | CX31: =VLOOKUP(B31,'CIA MARKS'!C28:DN96,116,FALSE) -> 43 | CY31: =VLOOKUP(B31,'CIA MARKS'!C28:DO96,117,FALSE) -> 40 | CZ31: =VLOOKUP(B31,'CIA MARKS'!C28:DP96,118,FALSE) -> 45 | DA31: ='CIA MARKS'!EJ28 -> 45 | DB31: =DC31/2 -> 41.5 | DC31: 83 | DD31: A+ | DF31: =IF(D$7="YES",'CIA MARKS'!DX28,"") | DG31: =IF(D$8="YES",'CIA MARKS'!EH28,"") | DH31: =IF(D$9="YES",'CIA MARKS'!EJ28,"") -> 45 | DI31: 41.5 | DR31: =SUM(DP31:DQ31) -> 0
A32: 16 | B32: 1DS23AI017 | C32: CHAITRA R | D32: 9 | H32: 10 | L32: 8 | X32: 8 | AB32: 10 | AJ32: 10 | AN32: 9 | AR32: 5 | AZ32: 8 | BH32: 4 | BP32: 10 | BT32: 10 | BX32: 9 | CF32: 8 | CN32: 7 | CV32: 7 | CW32: 10 | CX32: =VLOOKUP(B32,'CIA MARKS'!C29:DN97,116,FALSE) -> 45 | CY32: =VLOOKUP(B32,'CIA MARKS'!C29:DO97,117,FALSE) -> 36 | CZ32: =VLOOKUP(B32,'CIA MARKS'!C29:DP97,118,FALSE) -> 44 | DA32: ='CIA MARKS'!EJ29 -> 45 | DB32: =DC32/2 -> 41 | DC32: 82 | DD32: A+ | DF32: =IF(D$7="YES",'CIA MARKS'!DX29,"") | DG32: =IF(D$8="YES",'CIA MARKS'!EH29,"") | DH32: =IF(D$9="YES",'CIA MARKS'!EJ29,"") -> 45 | DI32: 41 | DR32: =SUM(DP32:DQ32) -> 0
A33: 17 | B33: 1DS23AI018 | C33: CHIRANTHAN REDDY H M | D33: 8 | L33: 3 | X33: 9 | AB33: 0 | AF33: 2 | AN33: 5 | AR33: 4 | BH33: 2 | BP33: 8 | BT33: 6 | BX33: 6 | CF33: 6 | CR33: 7 | CV33: 6 | CW33: 10 | CX33: =VLOOKUP(B33,'CIA MARKS'!C30:DN98,116,FALSE) -> 22 | CY33: =VLOOKUP(B33,'CIA MARKS'!C30:DO98,117,FALSE) -> 11 | CZ33: =VLOOKUP(B33,'CIA MARKS'!C30:DP98,118,FALSE) -> 33 | DA33: ='CIA MARKS'!EJ30 -> 34 | DB33: =DC33/2 -> 38.5 | DC33: 77 | DD33: A | DF33: =IF(D$7="YES",'CIA MARKS'!DX30,"") | DG33: =IF(D$8="YES",'CIA MARKS'!EH30,"") | DH33: =IF(D$9="YES",'CIA MARKS'!EJ30,"") -> 34 | DI33: 38.5 | DR33: =SUM(DP33:DQ33) -> 0
A34: 18 | B34: 1DS23AI019 | C34: DEVANSH GOYAL | D34: 9 | H34: 6 | P34: 8 | X34: 9 | AF34: 5 | AN34: 9 | AV34: 9 | BD34: 4 | BL34: 4 | BP34: 10 | BT34: 9 | CB34: 9 | CF34: 7 | CR34: 8 | CV34: 8 | CW34: 10 | CX34: =VLOOKUP(B34,'CIA MARKS'!C31:DN99,116,FALSE) -> 37 | CY34: =VLOOKUP(B34,'CIA MARKS'!C31:DO99,117,FALSE) -> 26 | CZ34: =VLOOKUP(B34,'CIA MARKS'!C31:DP99,118,FALSE) -> 43 | DA34: ='CIA MARKS'!EJ31 -> 43 | DB34: =DC34/2 -> 41.5 | DC34: 83 | DD34: A+ | DF34: =IF(D$7="YES",'CIA MARKS'!DX31,"") | DG34: =IF(D$8="YES",'CIA MARKS'!EH31,"") | DH34: =IF(D$9="YES",'CIA MARKS'!EJ31,"") -> 43 | DI34: 41.5 | DR34: =SUM(DP34:DQ34) -> 0
A35: 19 | B35: 1DS23AI020 | C35: DEVARAJA KATTI | D35: 0 | P35: 6 | T35: 2 | AF35: 3 | AJ35: 7 | AN35: 9 | AV35: 8 | AZ35: 6 | BH35: 7 | BP35: 7 | BT35: 6 | BX35: 8 | CF35: 8 | CR35: 5 | CV35: 8 | CW35: 10 | CX35: =VLOOKUP(B35,'CIA MARKS'!C32:DN100,116,FALSE) -> 11 | CY35: =VLOOKUP(B35,'CIA MARKS'!C32:DO100,117,FALSE) -> 37 | CZ35: =VLOOKUP(B35,'CIA MARKS'!C32:DP100,118,FALSE) -> 34 | DA35: ='CIA MARKS'!EJ32 -> 39 | DB35: =DC35/2 -> 40 | DC35: 80 | DD35: A | DF35: =IF(D$7="YES",'CIA MARKS'!DX32,"") | DG35: =IF(D$8="YES",'CIA MARKS'!EH32,"") | DH35: =IF(D$9="YES",'CIA MARKS'!EJ32,"") -> 39 | DI35: 40 | DR35: =SUM(DP35:DQ35) -> 0
A36: 20 | B36: 1DS23AI021 | C36: DILEEP KARABASAPPA HONNATTER | D36: 7 | L36: 4 | AF36: 1 | AN36: 2 | AV36: 6 | BH36: 2 | BP36: 7 | BT36: 6 | BX36: 8 | CF36: 6 | CN36: 6 | CV36: 6 | CW36: 10 | CX36: =VLOOKUP(B36,'CIA MARKS'!C33:DN101,116,FALSE) -> 12 | CY36: =VLOOKUP(B36,'CIA MARKS'!C33:DO101,117,FALSE) -> 10 | CZ36: =VLOOKUP(B36,'CIA MARKS'!C33:DP101,118,FALSE) -> 33 | DA36: ='CIA MARKS'!EJ33 -> 32 | DB36: =DC36/2 -> 28 | DC36: 56 | DD36: B+ | DF36: =IF(D$7="YES",'CIA MARKS'!DX33,"") | DG36: =IF(D$8="YES",'CIA MARKS'!EH33,"") | DH36: =IF(D$9="YES",'CIA MARKS'!EJ33,"") -> 32 | DI36: 28 | DR36: =SUM(DP36:DQ36) -> 0
A37: 21 | B37: 1DS23AI022 | C37: DRUTHI U S | D37: 8 | H37: 3 | L37: 6 | T37: 8 | AF37: 1 | AJ37: 0 | AN37: 0 | AR37: 0 | AZ37: 3 | BH37: 1 | BP37: 8 | BT37: 6 | BX37: 8 | CF37: 8 | CN37: 6 | CV37: 8 | CW37: 10 | CX37: =VLOOKUP(B37,'CIA MARKS'!C34:DN102,116,FALSE) -> 26 | CY37: =VLOOKUP(B37,'CIA MARKS'!C34:DO102,117,FALSE) -> 4 | CZ37: =VLOOKUP(B37,'CIA MARKS'!C34:DP102,118,FALSE) -> 36 | DA37: ='CIA MARKS'!EJ34 -> 33 | DB37: =DC37/2 -> 32.5 | DC37: 65 | DD37: B+ | DF37: =IF(D$7="YES",'CIA MARKS'!DX34,"") | DG37: =IF(D$8="YES",'CIA MARKS'!EH34,"") | DH37: =IF(D$9="YES",'CIA MARKS'!EJ34,"") -> 33 | DI37: 32.5 | DR37: =SUM(DP37:DQ37) -> 0
A38: 22 | B38: 1DS23AI023 | C38: E JAYA SIDDARTHA | D38: 10 | H38: 9 | L38: 9 | T38: 9 | AF38: 7 | AN38: 7 | AV38: 8 | AZ38: 9 | BL38: 10 | BP38: 10 | BT38: 9 | BX38: 10 | CJ38: 9 | CN38: 9 | CV38: 8 | CW38: 10 | CX38: =VLOOKUP(B38,'CIA MARKS'!C35:DN103,116,FALSE) -> 44 | CY38: =VLOOKUP(B38,'CIA MARKS'!C35:DO103,117,FALSE) -> 34 | CZ38: =VLOOKUP(B38,'CIA MARKS'!C35:DP103,118,FALSE) -> 47 | DA38: ='CIA MARKS'!EJ35 -> 46 | DB38: =DC38/2 -> 39 | DC38: 78 | DD38: A+ | DF38: =IF(D$7="YES",'CIA MARKS'!DX35,"") | DG38: =IF(D$8="YES",'CIA MARKS'!EH35,"") | DH38: =IF(D$9="YES",'CIA MARKS'!EJ35,"") -> 46 | DI38: 39 | DR38: =SUM(DP38:DQ38) -> 0
A39: 23 | B39: 1DS23AI024 | C39: FARIA AHMED | D39: 9 | H39: 5 | L39: 6 | X39: 9 | AB39: 3 | AN39: 9 | AV39: 9 | AZ39: 4 | BH39: 6 | BP39: 10 | BX39: 8 | CF39: 9 | CR39: 6 | CV39: 6 | CW39: 10 | CX39: =VLOOKUP(B39,'CIA MARKS'!C36:DN104,116,FALSE) -> 32 | CY39: =VLOOKUP(B39,'CIA MARKS'!C36:DO104,117,FALSE) -> 28 | CZ39: =VLOOKUP(B39,'CIA MARKS'!C36:DP104,118,FALSE) -> 33 | DA39: ='CIA MARKS'!EJ36 -> 39 | DB39: =DC39/2 -> 28 | DC39: 56 | DD39: B+ | DF39: =IF(D$7="YES",'CIA MARKS'!DX36,"") | DG39: =IF(D$8="YES",'CIA MARKS'!EH36,"") | DH39: =IF(D$9="YES",'CIA MARKS'!EJ36,"") -> 39 | DI39: 28 | DR39: =SUM(DP39:DQ39) -> 0
A40: 24 | B40: 1DS23AI025 | C40: G M VARSHINI | D40: 8 | H40: 4 | L40: 5 | X40: 9 | AF40: 8 | AJ40: 6 | AN40: 10 | AV40: 8 | AZ40: 6 | BL40: 2 | BT40: 8 | BX40: 8 | CB40: 8 | CF40: 8 | CR40: 3 | CV40: 6 | CW40: 10 | CX40: =VLOOKUP(B40,'CIA MARKS'!C37:DN105,116,FALSE) -> 34 | CY40: =VLOOKUP(B40,'CIA MARKS'!C37:DO105,117,FALSE) -> 32 | CZ40: =VLOOKUP(B40,'CIA MARKS'!C37:DP105,118,FALSE) -> 27 | DA40: ='CIA MARKS'!EJ37 -> 39 | DB40: =DC40/2 -> 32.5 | DC40: 65 | DD40: A | DF40: =IF(D$7="YES",'CIA MARKS'!DX37,"") | DG40: =IF(D$8="YES",'CIA MARKS'!EH37,"") | DH40: =IF(D$9="YES",'CIA MARKS'!EJ37,"") -> 39 | DI40: 32.5 | DR40: =SUM(DP40:DQ40) -> 0
A41: 25 | B41: 1DS23AI026 | C41: GANGEDDULA JOSHITH REDDY | D41: 7 | H41: 2 | L41: 2 | X41: 9 | AF41: 3 | AJ41: 6 | AR41: 8 | BD41: 0 | BH41: 4 | BP41: 8 | BT41: 6 | BX41: 8 | CF41: 8 | CN41: 2 | CV41: 6 | CW41: 10 | CX41: =VLOOKUP(B41,'CIA MARKS'!C38:DN106,116,FALSE) -> 23 | CY41: =VLOOKUP(B41,'CIA MARKS'!C38:DO106,117,FALSE) -> 18 | CZ41: =VLOOKUP(B41,'CIA MARKS'!C38:DP106,118,FALSE) -> 32 | DA41: ='CIA MARKS'!EJ38 -> 37 | DB41: =DC41/2 -> 25.5 | DC41: 51 | DD41: B+ | DF41: =IF(D$7="YES",'CIA MARKS'!DX38,"") | DG41: =IF(D$8="YES",'CIA MARKS'!EH38,"") | DH41: =IF(D$9="YES",'CIA MARKS'!EJ38,"") -> 37 | DI41: 25.5 | DR41: =SUM(DP41:DQ41) -> 0
...

Sheet Lab
D3: Continuous Internal Evaluation-(CIE) | G3: Test | J3: FINAL LAB MARKS
C4: POs Mapped | F4: 0,5,9 | I4: 0,5,9,10,11 | J4: 0,5,9,10,11
C5: COs mapped | F5: 5 | I5: 6 | J5: 5,6
C6: Maximum Marks | D6: 0 | E6: 0 | F6: 30 | G6: 0 | H6: 0 | I6: 20 | J6: =SUM(D6:I6) -> 50
C7: Marks to reach Performance (60% and above of Max. Marks) | D7: =0.6*D6 -> 0 | E7: =0.6*E6 -> 0 | F7: =0.6*F6 -> 18 | G7: =0.6*G6 -> 0 | H7: =0.6*H6 -> 0 | I7: =0.6*I6 -> 12 | J7: =0.6*J6 -> 30
A8: Sl No. | B8: USN | C8: Names | D8: COMPONENT-1 | G8: COMPONENT-2 | J8: CIA | K8: SEE
A9: 1 | B9: =Theory!B17 -> 1DS23AI001 | C9: =Theory!C17 -> AAYUSH PANDEY | F9: 28 | I9: 10 | J9: =SUM(D9:I9) -> 38
A10: 2 | B10: =Theory!B18 -> 1DS23AI002 | C10: =Theory!C18 -> ABHINAND PRAMEESH | F10: 30 | I10: 20 | J10: =SUM(D10:I10) -> 50
A11: 3 | B11: =Theory!B19 -> 1DS23AI003 | C11: =Theory!C19 -> ABHISHEK SINGH | F11: 25 | I11: 10 | J11: =SUM(D11:I11) -> 35
A12: 4 | B12: =Theory!B20 -> 1DS23AI004 | C12: =Theory!C20 -> ABHISHEK V | F12: 28 | I12: 15 | J12: =SUM(D12:I12) -> 43
A13: 5 | B13: =Theory!B21 -> 1DS23AI005 | C13: =Theory!C21 -> ADITYA B RAWANAWAR | F13: 27 | I13: 19 | J13: =SUM(D13:I13) -> 46
A14: 6 | B14: =Theory!B22 -> 1DS23AI006 | C14: =Theory!C22 -> ADITYA MUTHUSAMY A | F14: 25 | I14: 8 | J14: =SUM(D14:I14) -> 33
A15: 7 | B15: =Theory!B23 -> 1DS23AI007 | C15: =Theory!C23 -> ADNAN SAMEER ANEKATTI | F15: 25 | I15: 8 | J15: =SUM(D15:I15) -> 33
A16: 8 | B16: =Theory!B24 -> 1DS23AI008 | C16: =Theory!C24 -> AKSHADHA SINGH | F16: 25 | I16: 8 | J16: =SUM(D16:I16) -> 33
A17: 9 | B17: =Theory!B25 -> 1DS23AI010 | C17: =Theory!C25 -> ANIMESH UPADHYAY | F17: 25 | I17: 8 | J17: =SUM(D17:I17) -> 33
A18: 10 | B18: =Theory!B26 -> 1DS23AI011 | C18: =Theory!C26 -> ASHWINI GANESH RATOD | F18: 26 | I18: 16 | J18: =SUM(D18:I18) -> 42
A19: 11 | B19: =Theory!B27 -> 1DS23AI012 | C19: =Theory!C27 -> AVIDUTT PUROHIT | F19: 25 | I19: 10 | J19: =SUM(D19:I19) -> 35
A20: 12 | B20: =Theory!B28 -> 1DS23AI013 | C20: =Theory!C28 -> B N SHARATH | F20: 28 | I20: 18 | J20: =SUM(D20:I20) -> 46
... A76: 68 | B76: =Theory!B84 -> 1DS24AI406 | C76: =Theory!C84 -> QALIM INDIKAR | F76: 28 | I76: 15 | J76: =SUM(D76:I76) -> 43
A77: 69 | B77: =Theory!B85 -> 0 | C77: =Theory!C85 -> 0 | J77: =SUM(D77:I77) -> 0
A78: 70 | B78: =Theory!B86 -> 0 | C78: =Theory!C86 -> 0 | J78: =SUM(D78:I78) -> 0
C82: A=No. of Students Attempted the Question | D82: =COUNTIFS(D9:D78,"<>AB",D9:D78,"<>NA",D9:D78,"<>") -> 0 | E82: =COUNTIFS(E9:E78,"<>AB",E9:E78,"<>NA",E9:E78,"<>") -> 0 | F82: =COUNTIFS(F9:F78,"<>AB",F9:F78,"<>NA",F9:F78,"<>") -> 68 | G82: =COUNTIFS(G9:G78,"<>AB",G9:G78,"<>NA",G9:G78,"<>") -> 0 | H82: =COUNTIFS(H9:H78,"<>AB",H9:H78,"<>NA",H9:H78,"<>") -> 0 | I82: =COUNTIFS(I9:I78,"<>AB",I9:I78,"<>NA",I9:I78,"<>") -> 68 | J82: =COUNTIFS(J9:J78,"<>AB",J9:J78,"<>NA",J9:J78,"<>") -> 70 | K82: =COUNTIFS(K12:K81,"<>AB",K12:K81,"<>NA",K12:K81,"<>") -> 0
C83: B=Sum of Marks > 60% | D83: =SUMIF(D9:D78,">="&D7,D9:D78) -> 0 | E83: =SUMIF(E9:E78,">="&E7,E9:E78) -> 0 | F83: =SUMIF(F9:F78,">="&F7,F9:F78) -> 1870 | G83: =SUMIF(G9:G78,">="&G7,G9:G78) -> 0 | H83: =SUMIF(H9:H78,">="&H7,H9:H78) -> 0 | I83: =SUMIF(I9:I78,">="&I7,I9:I78) -> 897 | J83: =SUMIF(J9:J78,">="&J7,J9:J78) -> 2931 | K83: =SUMIF(K12:K81,">="&K10,K12:K81) -> 0
C84: CO Attainment = B/A | D84: =IF(D82<>0,((D83/D82)/D6)*100,0) -> 0 | E84: =IF(E82<>0,((E83/E82)/E6)*100,0) -> 0 | F84: =IF(F82<>0,((F83/F82)/F6)*100,0) -> 91.666667 | G84: =IF(G82<>0,((G83/G82)/G6)*100,0) -> 0 | H84: =IF(H82<>0,((H83/H82)/H6)*100,0) -> 0 | I84: =IF(I82<>0,((I83/I82)/I6)*100,0) -> 65.955882 | J84: =IF(J82<>0,((J83/J82)/J6)*100,0) -> 83.742857 | K84: =VALUE(IF(K82<>0,(COUNTIF(K12:K81,"=S")*10+COUNTIF(K12:K81,"=A")*9+COUNTIF(K12:K81,"=B")*8+COUNTIF(K12:K81,"=C")*7+COUNTIF(K12:K81,"=D")*5+COUNTIF(K12:K81,"=E")*4)/(10*COUNTIF(K12:K81,"<>"&""))*100,0)) -> 0
C88: CO Attainment of LAB Total Percentage (Average) | D88: CO1 | E88: CO2 | F88: CO3 | G88: CO4 | H88: CO5 | I88: CO6 | J88: CO7 | K88: CO8 | L88: CO9 | M88: CO10 | N88: CO11 | O88: CO12
C89: CO Attainment | D89: =IF(COUNTIFS($D$5:$L$5,"=1",$D84:$L84,"<>0")=0,0,SUMIF($D$5:$L$5,"=1",$D84:$L84)/COUNTIFS($D$5:$L$5,"=1",$D84:$L84,"<>0")) -> 0 | E89: =IF(COUNTIFS($D$5:$L$5,"=2",$D84:$L84,"<>0")=0,0,SUMIF($D$5:$L$5,"=2",$D84:$L84)/COUNTIFS($D$5:$L$5,"=2",$D84:$L84,"<>0")) -> 0 | F89: =IF(COUNTIFS($D$5:$L$5,"=3",$D84:$L84,"<>0")=0,0,SUMIF($D$5:$L$5,"=3",$D84:$L84)/COUNTIFS($D$5:$L$5,"=3",$D84:$L84,"<>0")) -> 0 | G89: =IF(COUNTIFS($D$5:$I$5,"=4",$D84:$I84,"<>0")=0,0,SUMIF($D$5:$I$5,"=4",$D84:$I84)/COUNTIFS($D$5:$I$5,"=4",$D84:$I84,"<>0")) -> 0 | H89: =IF(COUNTIFS($D$5:$I$5,"=5",$D84:$I84,"<>0")=0,0,SUMIF($D$5:$I$5,"=5",$D84:$I84)/COUNTIFS($D$5:$I$5,"=5",$D84:$I84,"<>0")) -> 91.666667 | I89: =IF(COUNTIFS($D$5:$I$5,"=6",$D84:$I84,"<>0")=0,0,SUMIF($D$5:$I$5,"=6",$D84:$I84)/COUNTIFS($D$5:$I$5,"=6",$D84:$I84,"<>0")) -> 65.955882 | J89: =IF(COUNTIFS($D$5:$I$5,"=7",$D84:$I84,"<>0")=0,0,SUMIF($D$5:$I$5,"=7",$D84:$I84)/COUNTIFS($D$5:$I$5,"=7",$D84:$I84,"<>0")) -> 0 | K89: =IF(COUNTIFS($D$5:$I$5,"=8",$D84:$I84,"<>0")=0,0,SUMIF($D$5:$I$5,"=8",$D84:$I84)/COUNTIFS($D$5:$I$5,"=8",$D84:$I84,"<>0")) -> 0 | L89: =IF(COUNTIFS($D$5:$I$5,"=9",$D84:$I84,"<>0")=0,0,SUMIF($D$5:$I$5,"=9",$D84:$I84)/COUNTIFS($D$5:$I$5,"=9",$D84:$I84,"<>0")) -> 0 | M89: =IF(COUNTIFS($D$5:$I$5,"=10",$D84:$I84,"<>0")=0,0,SUMIF($D$5:$I$5,"=10",$D84:$I84)/COUNTIFS($D$5:$I$5,"=10",$D84:$I84,"<>0")) -> 0 | N89: =IF(COUNTIFS($D$5:$I$5,"=11",$D84:$I84,"<>0")=0,0,SUMIF($D$5:$I$5,"=11",$D84:$I84)/COUNTIFS($D$5:$I$5,"=11",$D84:$I84,"<>0")) -> 0 | O89: =IF(COUNTIFS($D$5:$I$5,"=12",$D84:$I84,"<>0")=0,0,SUMIF($D$5:$I$5,"=12",$D84:$I84)/COUNTIFS($D$5:$I$5,"=12",$D84:$I84,"<>0")) -> 0
C96: PO Attainment (LAB) | D96: PO1 | E96: PO2 | F96: PO3 | G96: PO4 | H96: PO5 | I96: PO6 | J96: PO7 | K96: PO8 | L96: PO9 | M96: PO10 | N96: PO11 | O96: PO12
C97: Case 1 | D97: =IF(COUNTIFS($D$4:$I$4,"=*,1,*",$D84:$I84,"<>0")=0,0,SUMIF($D$4:$I$4,"=*,1,*",$D84:$I84)/COUNTIFS($D$4:$I$4,"=*,1,*",$D84:$I84,"<>0")) -> 0 | E97: =IF(COUNTIFS($D$4:$I$4,"=*,2,*",$D84:$I84,"<>0")=0,0,SUMIF($D$4:$I$4,"=*,2,*",$D84:$I84)/COUNTIFS($D$4:$I$4,"=*,2,*",$D84:$I84,"<>0")) -> 0 | F97: =IF(COUNTIFS($D$4:$I$4,"=*,3,*",$D84:$I84,"<>0")=0,0,SUMIF($D$4:$I$4,"=*,3,*",$D84:$I84)/COUNTIFS($D$4:$I$4,"=*,3,*",$D84:$I84,"<>0")) -> 0 | G97: =IF(COUNTIFS($D$4:$I$4,"=*,4,*",$D84:$I84,"<>0")=0,0,SUMIF($D$4:$I$4,"=*,4,*",$D84:$I84)/COUNTIFS($D$4:$I$4,"=*,4,*",$D84:$I84,"<>0")) -> 0 | H97: =IF(COUNTIFS($D$4:$I$4,"=*,5,*",$D84:$I84,"<>0")=0,0,SUMIF($D$4:$I$4,"=*,5,*",$D84:$I84)/COUNTIFS($D$4:$I$4,"=*,5,*",$D84:$I84,"<>0")) -> 78.811275 | I97: =IF(COUNTIFS($D$4:$I$4,"=*,6,*",$D84:$I84,"<>0")=0,0,SUMIF($D$4:$I$4,"=*,6,*",$D84:$I84)/COUNTIFS($D$4:$I$4,"=*,6,*",$D84:$I84,"<>0")) -> 0 | J97: =IF(COUNTIFS($D$4:$I$4,"=*,7,*",$D84:$I84,"<>0")=0,0,SUMIF($D$4:$I$4,"=*,7,*",$D84:$I84)/COUNTIFS($D$4:$I$4,"=*,7,*",$D84:$I84,"<>0")) -> 0 | K97: =IF(COUNTIFS($D$4:$I$4,"=*,8,*",$D84:$I84,"<>0")=0,0,SUMIF($D$4:$I$4,"=*,8,*",$D84:$I84)/COUNTIFS($D$4:$I$4,"=*,8,*",$D84:$I84,"<>0")) -> 0 | L97: =IF(COUNTIFS($D$4:$I$4,"=*,9,*",$D84:$I84,"<>0")=0,0,SUMIF($D$4:$I$4,"=*,9,*",$D84:$I84)/COUNTIFS($D$4:$I$4,"=*,9,*",$D84:$I84,"<>0")) -> 65.955882 | M97: =IF(COUNTIFS($D$4:$I$4,"=*,10,*",$D84:$I84,"<>0")=0,0,SUMIF($D$4:$I$4,"=*,10,*",$D84:$I84)/COUNTIFS($D$4:$I$4,"=*,10,*",$D84:$I84,"<>0")) -> 65.955882 | N97: =IF(COUNTIFS($D$4:$I$4,"=*,11,*",$D84:$I84,"<>0")=0,0,SUMIF($D$4:$I$4,"=*,11,*",$D84:$I84)/COUNTIFS($D$4:$I$4,"=*,11,*",$D84:$I84,"<>0")) -> 0 | O97: =IF(COUNTIFS($D$4:$I$4,"=*,12,*",$D84:$I84,"<>0")=0,0,SUMIF($D$4:$I$4,"=*,12,*",$D84:$I84)/COUNTIFS($D$4:$I$4,"=*,12,*",$D84:$I84,"<>0")) -> 0

Sheet CIA MARKS
A2: =Theory!A7 -> STAND ALONE THEORY | C2: =Theory!D7 -> NO
A3: =Theory!A8 -> STAND ALONE LAB | C3: =Theory!D8 -> NO
A4: =Theory!A9 -> IPCC | C4: =Theory!D9 -> Yes
A5: =Theory!A4 -> Academic Year : 2024 -25
A6: =Theory!D4 -> Scheme :2022-26
A7: =Theory!A6 -> COURSE TITLE :DBMS | D7: =Theory!A10 -> Faculty : Anupama V P | S7: CO # | V7: CO1 | W7: CO2 | X7: CO3 | Y7: CO4 | Z7: CO5 | AA7: CO6
A8: =Theory!A5 -> COURSE CODE : 22AI33 | S8: CO Targets: | V8: 60 | W8: 60 | X8: 60 | Y8: 60 | Z8: 60 | AA8: 60 | AO8: IA1-TOTAL | CA8: IA2-TOTAL | DM8: IA3-TOTAL
A9: =Theory!Q4 -> Semester : 3rd | D9: IAT-1 | AP9: IAT-2 | CB9: IAT-3 | DN9: CIA-1 (50) | DO9: CIA-2 (50) | DP9: CIA-3 (50) | DQ9: CIA-1 (30) | DR9: CIA-2 (30) | DS9: CIA-3 (30) | DT9: AVG CIA (30) | DU9: AAT (10) | DV9: QUIZ (10) | DW9: AAT+QUIZ (10+10) | DX9: THEORY CIA (50) | DY9: THEORY CIA (30) | DZ9: Lab-CIE (30) | ED9: LAB IA (20) | EH9: LAB (50) | EI9: LAB CIA (20) | EJ9: CIA | EK9: SEE | EM9: ATTENDANCE FOR CSV FILE
A10: Question maps to which course outcome? | D10: =Theory!D12 -> 0,1 | E10: =Theory!E12 -> 0 | F10: =Theory!F12 -> 0 | G10: =Theory!G12 -> 0 | I10: =Theory!H12 -> 0,4 | J10: =Theory!I12 -> 0 | K10: =Theory!J12 -> 0 | L10: =Theory!K12 -> 0 | N10: =Theory!L12 -> 0,2 | O10: =Theory!M12 -> 0 | P10: =Theory!N12 -> 0 | Q10: =Theory!O12 -> 0 | R10: =Theory!P12 -> 0,2 | S10: =Theory!Q12 -> 0 | T10: =Theory!R12 -> 0 | U10: =Theory!S12 -> 0 | W10: =Theory!T12 -> 0,1 | X10: =Theory!U12 -> 0 | Y10: =Theory!V12 -> 0 | Z10: =Theory!W12 -> 0 | AA10: =Theory!X12 -> 0,1 | AB10: =Theory!Y12 -> 0 | AC10: =Theory!Z12 -> 0 | AD10: =Theory!AA12 -> 0 | AF10: =Theory!AB12 -> 0,4 | AG10: =Theory!AC12 -> 0 | AH10: =Theory!AD12 -> 0 | AI10: =Theory!AE12 -> 0 | AJ10: =Theory!AF12 -> 0,4 | AK10: =Theory!AG12 -> 0 | AL10: =Theory!AH12 -> 0 | AM10: =Theory!AI12 -> 0 | AP10: =Theory!AJ12 -> 0,4 | AQ10: =Theory!AK12 -> 0 | AR10: =Theory!AL12 -> 0 | AS10: =Theory!AM12 -> 0 | AU10: =Theory!AN12 -> 0,3 | AV10: =Theory!AO12 -> 0 | AW10: =Theory!AP12 -> 0 | AX10: =Theory!AQ12 -> 0 | AZ10: =Theory!AR12 -> 0,4 | BA10: =Theory!AS12 -> 0 | BB10: =Theory!AT12 -> 0 | BC10: =Theory!AU12 -> 0 | BD10: =Theory!AV12 -> 0,4 | BE10: =Theory!AW12 -> 0 | BF10: =Theory!AX12 -> 0 | BG10: =Theory!AY12 -> 0 | BI10: =Theory!AZ12 -> 0,4 | BJ10: =Theory!BA12 -> 0 | BK10: =Theory!BB12 -> 0 | BL10: =Theory!BC12 -> 0 | BM10: =Theory!BD12 -> 0,4 | BN10: =Theory!BE12 -> 0 | BO10: =Theory!BF12 -> 0 | BP10: =Theory!BG12 -> 0 | BR10: =Theory!BH12 -> 0,3 | BS10: =Theory!BI12 -> 0 | BT10: =Theory!BJ12 -> 0 | BU10: =Theory!BK12 -> 0 | BV10: =Theory!BL12 -> 0,3 | BW10: =Theory!BM12 -> 0 | BX10: =Theory!BN12 -> 0 | BY10: =Theory!BO12 -> 0 | CB10: =Theory!BP12 -> 0,3 | CC10: =Theory!BQ12 -> 0 | CD10: =Theory!BR12 -> 0 | CE10: =Theory!BS12 -> 0 | CG10: =Theory!BT12 -> 0,5 | CH10: =Theory!BU12 -> 0 | CI10: =Theory!BV12 -> 0 | CJ10: =Theory!BW12 -> 0 | CL10: =Theory!BX12 -> 0,3 | CM10: =Theory!BY12 -> 0 | CN10: =Theory!BZ12 -> 0 | CO10: =Theory!CA12 -> 0 | CP10: =Theory!CB12 -> 0,3 | CQ10: =Theory!CC12 -> 0 | CR10: =Theory!CD12 -> 0 | CS10: =Theory!CE12 -> 0 | CU10: =Theory!CF12 -> 0,5 | CV10: =Theory!CG12 -> 0 | CW10: =Theory!CH12 -> 0 | CX10: =Theory!CI12 -> 0 | CY10: =Theory!CJ12 -> 0,5 | CZ10: =Theory!CK12 -> 0 | DA10: =Theory!CL12 -> 0 | DB10: =Theory!CM12 -> 0 | DD10: =Theory!CN12 -> 0,5 | DE10: =Theory!CO12 -> 0 | DF10: =Theory!CP12 -> 0 | DG10: =Theory!CQ12 -> 0 | DH10: =Theory!CR12 -> 0,5 | DI10: =Theory!CS12 -> 0 | DJ10: =Theory!CT12 -> 0 | DK10: =Theory!CU12 -> 0 | DY10: 0,1,2,3,4 | EI10: 0,5,6 | EJ10: 0,1,2,3,4,5 | EK10: 0,1,2,3,4 | EM10: ATTND (11/12) | EN10: ATTND (11/24) | EO10: ATTND (34/40) | EP10: ATTND (34/40) | EQ10: ATTND (11/12) | ER10: ATT-THEORY (34/40) | ES10: ATT-LAB (11/12)
D11: =Theory!D16 -> Q1A | E11: =Theory!E16 -> Q1B | F11: =Theory!F16 -> Q1C | G11: =Theory!G16 -> Q1D | I11: =Theory!H16 -> Q2A | J11: =Theory!I16 -> Q2B | K11: =Theory!J16 -> Q2C | L11: =Theory!K16 -> Q2D | N11: =Theory!L16 -> Q3A | O11: =Theory!M16 -> Q3B | P11: =Theory!N16 -> Q3C | Q11: =Theory!O16 -> Q3D | R11: =Theory!P16 -> Q4A | S11: =Theory!Q16 -> Q4B | T11: =Theory!R16 -> Q4C | U11: =Theory!S16 -> Q4D | W11: =Theory!T16 -> Q5A | X11: =Theory!U16 -> Q5B | Y11: =Theory!V16 -> Q5C | Z11: =Theory!W16 -> Q5D | AA11: =Theory!X16 -> Q6A | AB11: =Theory!Y16 -> Q6B | AC11: =Theory!Z16 -> Q6C | AD11: =Theory!AA16 -> Q6D | AF11: =Theory!AB16 -> Q7A | AG11: =Theory!AC16 -> Q7B | AH11: =Theory!AD16 -> Q7C | AI11: =Theory!AE16 -> Q7D | AJ11: =Theory!AF16 -> Q8A | AK11: =Theory!AG16 -> Q8B | AL11: =Theory!AH16 -> Q8C | AM11: =Theory!AI16 -> Q8D | AP11: =Theory!AJ16 -> Q1A | AQ11: =Theory!AK16 -> Q1A | AR11: =Theory!AL16 -> Q1C | AS11: =Theory!AM16 -> Q1D | AU11: =Theory!AN16 -> Q2A | AV11: =Theory!AO16 -> Q2A | AW11: =Theory!AP16 -> Q2C | AX11: =Theory!AQ16 -> Q2D | AZ11: =Theory!AR16 -> Q3A | BA11: =Theory!AS16 -> Q3B | BB11: =Theory!AT16 -> Q3C | BC11: =Theory!AU16 -> Q3D | BD11: =Theory!AV16 -> Q4A | BE11: =Theory!AW16 -> Q4B | BF11: =Theory!AX16 -> Q4C | BG11: =Theory!AY16 -> Q4D | BI11: =Theory!AZ16 -> Q5A | BJ11: =Theory!BA16 -> Q5B | BK11: =Theory!BB16 -> Q5C | BL11: =Theory!BC16 -> Q5D | BM11: =Theory!BD16 -> Q6A | BN11: =Theory!BE16 -> Q6B | BO11: =Theory!BF16 -> Q6C | BP11: =Theory!BG16 -> Q6D | BR11: =Theory!BH16 -> Q7A | BS11: =Theory!BI16 -> Q7B | BT11: =Theory!BJ16 -> Q7C | BU11: =Theory!BK16 -> Q7D | BV11: =Theory!BL16 -> Q8A | BW11: =Theory!BM16 -> Q8B | BX11: =Theory!BN16 -> Q8C | BY11: =Theory!BO16 -> Q8D | CB11: =Theory!BP16 -> Q1A | CC11: =Theory!BQ16 -> Q1B | CD11: =Theory!BR16 -> Q1C | CE11: =Theory!BS16 -> Q1D | CG11: =Theory!BT16 -> Q2A | CH11: =Theory!BU16 -> Q2B | CI11: =Theory!BV16 -> Q2C | CJ11: =Theory!BW16 -> Q2D | CL11: =Theory!BX16 -> Q3A | CM11: =Theory!BY16 -> Q3B | CN11: =Theory!BZ16 -> Q3C | CO11: =Theory!CA16 -> Q3D | CP11: =Theory!CB16 -> Q4A | CQ11: =Theory!CC16 -> Q4B | CR11: =Theory!CD16 -> Q4C | CS11: =Theory!CE16 -> Q4D | CU11: =Theory!CF16 -> Q5A | CV11: =Theory!CG16 -> Q5B | CW11: =Theory!CH16 -> Q5C | CX11: =Theory!CI16 -> Q5D | CY11: =Theory!CJ16 -> Q6A | CZ11: =Theory!CK16 -> Q6B | DA11: =Theory!CL16 -> Q6C | DB11: =Theory!CM16 -> Q6D | DD11: =Theory!CN16 -> Q7A | DE11: =Theory!CO16 -> Q7B | DF11: =Theory!CP16 -> Q7C | DG11: =Theory!CQ16 -> Q7D | DH11: =Theory!CR16 -> Q8A | DI11: =Theory!CS16 -> Q8B | DJ11: =Theory!CT16 -> Q8C | DK11: =Theory!CU16 -> Q8D | DT11: CIA | DU11: AAT | DV11: QUIZ | DW11: AAT+QUIZ | DX11: THEORY CIA (50) | DY11: THEORY CIA (30) | EC11: Lab-CIE (30) | EG11: LAB IA (20) | EH11: LAB | EI11: LAB CIA (20) | EJ11: CIA (50) | EK11: SEE (50) | EM11: CREDIT-1 | EN11: CREDIT-2 | EO11: CREDIT-3 | EP11: CREDIT-4 | EQ11: LAB CREDIT-1 | ER11: CREDIT-4
A12: Sl NO | B12: Name | C12: USN | DT12: TEST (12/30) | DW12: AAT (8/20) | DX12: STAND ALONE THEORY | EC12: LAB-CLASS WORK (12/30) | EG12: LAB-TEST (8/20) | EH12: STAND ALONE LAB | EJ12: IPCC | EK12: SEE | EM12: STAND ALONE THEORY ATTENDANCE | EN12: STAND ALONE THEORY ATTENDANCE | EO12: STAND ALONE THEORY ATTENDANCE | EP12: STAND ALONE THEORY ATTENDANCE | EQ12: STAND ALONE LAB ATTENDANCE | ER12: IPCC THEORY ATTENDANCE | ES12: IPCC LAB ATTENDANCE | ET12: IPCC TOTAL ATTENDANCE
C13: MAX MARKS | D13: =Theory!D14 -> 10 | E13: =Theory!E14 -> 0 | F13: =Theory!F14 -> 0 | G13: =Theory!G14 -> 0 | H13: =SUM(D13:G13) -> 10 | I13: =Theory!H14 -> 10 | J13: =Theory!I14 -> 0 | K13: =Theory!J14 -> 0 | L13: =Theory!K14 -> 0 | M13: =SUM(I13:L13) -> 10 | N13: =Theory!L14 -> 10 | O13: =Theory!M14 -> 0 | P13: =Theory!N14 -> 0 | Q13: =Theory!O14 -> 0 | R13: =Theory!P14 -> 10 | S13: =Theory!Q14 -> 0 | T13: =Theory!R14 -> 0 | U13: =Theory!S14 -> 0 | V13: =MAX(SUM(N13:Q13),SUM(R13:U13)) -> 10 | W13: =Theory!T14 -> 10 | X13: =Theory!U14 -> 0 | Y13: =Theory!V14 -> 0 | Z13: =Theory!W14 -> 0 | AA13: =Theory!X14 -> 10 | AB13: =Theory!Y14 -> 0 | AC13: =Theory!Z14 -> 0 | AD13: =Theory!AA14 -> 0 | AE13: =MAX(SUM(W13:Z13),SUM(AA13:AD13)) -> 10 | AF13: =Theory!AB14 -> 10 | AG13: =Theory!AC14 -> 0 | AH13: =Theory!AD14 -> 0 | AI13: =Theory!AE14 -> 0 | AJ13: =Theory!AF14 -> 10 | AK13: =Theory!AG14 -> 0 | AL13: =Theory!AH14 -> 0 | AM13: =Theory!AI14 -> 0 | AN13: =MAX(SUM(AF13:AI13),SUM(AJ13:AM13)) -> 10 | AO13: =SUM(H13,M13,V13,AE13,AN13) -> 50 | AP13: =Theory!AJ14 -> 10 | AQ13: =Theory!AK14 -> 0 | AR13: =Theory!AL14 -> 0 | AS13: =Theory!AM14 -> 0 | AT13: =SUM(AP13:AS13) -> 10 | AU13: =Theory!AN14 -> 10 | AV13: =Theory!AO14 -> 0 | AW13: =Theory!AP14 -> 0 | AX13: =Theory!AQ14 -> 0 | AY13: =SUM(AU13:AX13) -> 10 | AZ13: =Theory!AR14 -> 10 | BA13: =Theory!AS14 -> 0 | BB13: =Theory!AT14 -> 0 | BC13: =Theory!AU14 -> 0 | BD13: =Theory!AV14 -> 10 | BE13: =Theory!AW14 -> 0 | BF13: =Theory!AX14 -> 0 | BG13: =Theory!AY14 -> 0 | BH13: =MAX(SUM(AZ13:BC13),SUM(BD13:BG13)) -> 10 | BI13: =Theory!AZ14 -> 10 | BJ13: =Theory!BA14 -> 0 | BK13: =Theory!BB14 -> 0 | BL13: =Theory!BC14 -> 0 | BM13: =Theory!BD14 -> 10 | BN13: =Theory!BE14 -> 0 | BO13: =Theory!BF14 -> 0 | BP13: =Theory!BG14 -> 0 | BQ13: =MAX(SUM(BI13:BL13),SUM(BM13:BP13)) -> 10 | BR13: =Theory!BH14 -> 10 | BS13: =Theory!BI14 -> 0 | BT13: =Theory!BJ14 -> 0 | BU13: =Theory!BK14 -> 0 | BV13: =Theory!BL14 -> 10 | BW13: =Theory!BM14 -> 0 | BX13: =Theory!BN14 -> 0 | BY13: =Theory!BO14 -> 0 | BZ13: =MAX(SUM(BR13:BU13),SUM(BV13:BY13)) -> 10 | CA13: =SUM(AT13,AY13,BH13,BQ13,BZ13) -> 50 | CB13: =Theory!BP14 -> 10 | CC13: =Theory!BQ14 -> 0 | CD13: =Theory!BR14 -> 0 | CE13: =Theory!BS14 -> 0 | CF13: =SUM(CB13:CE13) -> 10 | CG13: =Theory!BT14 -> 10 | CH13: =Theory!BU14 -> 0 | CI13: =Theory!BV14 -> 0 | CJ13: =Theory!BW14 -> 0 | CK13: =SUM(CG13:CJ13) -> 10 | CL13: =Theory!BX14 -> 10 | CM13: =Theory!BY14 -> 0 | CN13: =Theory!BZ14 -> 0 | CO13: =Theory!CA14 -> 0 | CP13: =Theory!CB14 -> 10 | CQ13: =Theory!CC14 -> 0 | CR13: =Theory!CD14 -> 0 | CS13: =Theory!CE14 -> 0 | CT13: =MAX(SUM(CL13:CO13),SUM(CP13:CS13)) -> 10 | CU13: =Theory!CF14 -> 10 | CV13: =Theory!CG14 -> 0 | CW13: =Theory!CH14 -> 0 | CX13: =Theory!CI14 -> 0 | CY13: =Theory!CJ14 -> 10 | CZ13: =Theory!CK14 -> 0 | DA13: =Theory!CL14 -> 0 | DB13: =Theory!CM14 -> 0 | DC13: =MAX(SUM(CU13:CX13),SUM(CY13:DB13)) -> 10 | DD13: =Theory!CN14 -> 10 | DE13: =Theory!CO14 -> 0 | DF13: =Theory!CP14 -> 0 | DG13: =Theory!CQ14 -> 0 | DH13: =Theory!CR14 -> 10 | DI13: =Theory!CS14 -> 0 | DJ13: =Theory!CT14 -> 0 | DK13: =Theory!CU14 -> 0 | DL13: =MAX(SUM(DD13:DG13),SUM(DH13:DK13)) -> 10 | DM13: =SUM(CF13,CK13,CT13,DC13,DL13) -> 50 | DN13: =AO13 -> 50 | DO13: =CA13 -> 50 | DP13: =DM13 -> 50 | DQ13: =ROUND(30*DN13/50,0) -> 30 | DR13: =ROUND(30*DO13/50,0) -> 30 | DS13: =ROUND(30*DP13/50,0) -> 30 | DT13: =ROUND(AVERAGE(DQ13:DS13),0) -> 30 | DU13: =Theory!CV14 -> 10 | DV13: =Theory!CW14 -> 10 | DW13: =SUM(DU13:DV13) -> 20 | DX13: =SUM(DT13:DV13) -> 50 | DY13: =ROUND((30*DX13/50),0) -> 30 | DZ13: =Lab!D6 -> 0 | EA13: =Lab!E6 -> 0 | EB13: =Lab!F6 -> 30 | EC13: =SUM(DZ13:EB13) -> 30 | ED13: =Lab!G6 -> 0 | EE13: =Lab!H6 -> 0 | EF13: =Lab!I6 -> 20 | EG13: =SUM(ED13:EF13) -> 20 | EH13: =SUM(EC13,EG13) -> 50 | EI13: =ROUND((20*EH13/50),0) -> 20 | EJ13: =SUM(DY13,EI13) -> 50 | EK13: =Theory!DB14 -> 50 | EM13: 12 | EN13: 24 | EO13: 40 | EP13: 52 | EQ13: 12 | ER13: 40 | ES13: 12 | ET13: =SUM(ER13:ES13) -> 52
A14: 1 | B14: =Theory!C17 -> AAYUSH PANDEY | C14: =Theory!B17 -> 1DS23AI001 | D14: =VLOOKUP(C14,Theory!B17:D86,3,FALSE) -> 7 | E14: =VLOOKUP(C14,Theory!B17:E86,4,FALSE) -> 0 | F14: =VLOOKUP(C14,Theory!B17:F86,5,FALSE) -> 0 | G14: =VLOOKUP(C14,Theory!B17:G86,6,FALSE) -> 0 | H14: =SUM(D14:G14) -> 7 | I14: =VLOOKUP(C14,Theory!B17:H86,7,FALSE) -> 4 | J14: =VLOOKUP(C14,Theory!B17:I86,8,FALSE) -> 0 | K14: =VLOOKUP(C14,Theory!B17:J86,9,FALSE) -> 0 | L14: =VLOOKUP(C14,Theory!B17:K86,10,FALSE) -> 0 | M14: =SUM(I14:L14) -> 4 | N14: =VLOOKUP(C14,Theory!B17:L86,11,FALSE) -> 5 | O14: =VLOOKUP(C14,Theory!B17:M86,12,FALSE) -> 0 | P14: =VLOOKUP(C14,Theory!B17:N86,13,FALSE) -> 0 | Q14: =VLOOKUP(C14,Theory!B17:O86,14,FALSE) -> 0 | R14: =VLOOKUP(C14,Theory!B17:P86,15,FALSE) -> 0 | S14: =VLOOKUP(C14,Theory!B17:Q86,16,FALSE) -> 0 | T14: =VLOOKUP(C14,Theory!B17:R86,17,FALSE) -> 0 | U14: =VLOOKUP(C14,Theory!B17:S86,18,FALSE) -> 0 | V14: =MAX(SUM(N14:Q14),SUM(R14:U14)) -> 5 | W14: =VLOOKUP(C14,Theory!B17:T86,19,FALSE) -> 4 | X14: =VLOOKUP(C14,Theory!B17:U86,20,FALSE) -> 0 | Y14: =VLOOKUP(C14,Theory!B17:V86,21,FALSE) -> 0 | Z14: =VLOOKUP(C14,Theory!B17:W86,22,FALSE) -> 0 | AA14: =VLOOKUP(C14,Theory!B17:X86,23,FALSE) -> 0 | AB14: =VLOOKUP(C14,Theory!B17:Y86,24,FALSE) -> 0 | AC14: =VLOOKUP(C14,Theory!B17:Z86,25,FALSE) -> 0 | AD14: =VLOOKUP(C14,Theory!B17:AA86,26,FALSE) -> 0 | AE14: =MAX(SUM(W14:Z14),SUM(AA14:AD14)) -> 4 | AF14: =VLOOKUP(C14,Theory!B17:AB86,27,FALSE) -> 9 | AG14: =VLOOKUP(C14,Theory!B17:AC86,28,FALSE) -> 0 | AH14: =VLOOKUP(C14,Theory!B17:AD86,29,FALSE) -> 0 | AI14: =VLOOKUP(C14,Theory!B17:AE86,30,FALSE) -> 0 | AJ14: =VLOOKUP(C14,Theory!B17:AF86,31,FALSE) -> 0 | AK14: =VLOOKUP(C14,Theory!B17:AG86,32,FALSE) -> 0 | AL14: =VLOOKUP(C14,Theory!B17:AH86,33,FALSE) -> 0 | AM14: =VLOOKUP(C14,Theory!B17:AI86,34,FALSE) -> 0 | AN14: =MAX(SUM(AF14:AI14),SUM(AJ14:AM14)) -> 9 | AO14: =SUM(H14,M14,V14,AE14,AN14) -> 29 | AP14: =VLOOKUP(C14,Theory!B17:AJ86,35,FALSE) -> 5 | AQ14: =VLOOKUP(C14,Theory!B17:AK86,36,FALSE) -> 0 | AR14: =VLOOKUP(C14,Theory!B17:AL86,37,FALSE) -> 0 | AS14: =VLOOKUP(C14,Theory!B17:AM86,38,FALSE) -> 0 | AT14: =SUM(AP14:AS14) -> 5 | AU14: =VLOOKUP(C14,Theory!B17:AN86,39,FALSE) -> 4 | AV14: =VLOOKUP(C14,Theory!B17:AO86,40,FALSE) -> 0 | AW14: =VLOOKUP(C14,Theory!B17:AP86,41,FALSE) -> 0 | AX14: =VLOOKUP(C14,Theory!B17:AQ86,42,FALSE) -> 0 | AY14: =SUM(AU14:AX14) -> 4 | AZ14: =VLOOKUP(C14,Theory!B17:AR86,43,FALSE) -> 0 | BA14: =VLOOKUP(C14,Theory!B17:AS86,44,FALSE) -> 0 | BB14: =VLOOKUP(C14,Theory!B17:AT86,45,FALSE) -> 0 | BC14: =VLOOKUP(C14,Theory!B17:AU86,46,FALSE) -> 0 | BD14: =VLOOKUP(C14,Theory!B17:AV86,47,FALSE) -> 8 | BE14: =VLOOKUP(C14,Theory!B17:AW86,48,FALSE) -> 0 | BF14: =VLOOKUP(C14,Theory!B17:AX86,49,FALSE) -> 0 | BG14: =VLOOKUP(C14,Theory!B17:AY86,50,FALSE) -> 0 | BH14: =MAX(SUM(AZ14:BC14),SUM(BD14:BG14)) -> 8 | BI14: =VLOOKUP(C14,Theory!B17:AZ86,51,FALSE) -> 0 | BJ14: =VLOOKUP(C14,Theory!B17:BA86,52,FALSE) -> 0 | BK14: =VLOOKUP(C14,Theory!B17:BB86,53,FALSE) -> 0 | BL14: =VLOOKUP(C14,Theory!B17:BC86,54,FALSE) -> 0 | BM14: =VLOOKUP(C14,Theory!B17:BD86,55,FALSE) -> 0 | BN14: =VLOOKUP(C14,Theory!B17:BE86,56,FALSE) -> 0 | BO14: =VLOOKUP(C14,Theory!B17:BF86,57,FALSE) -> 0 | BP14: =VLOOKUP(C14,Theory!B17:BG86,58,FALSE) -> 0 | BQ14: =MAX(SUM(BI14:BL14),SUM(BM14:BP14)) -> 0 | BR14: =VLOOKUP(C14,Theory!B17:BH86,59,FALSE) -> 2 | BS14: =VLOOKUP(C14,Theory!B17:BI86,60,FALSE) -> 0 | BT14: =VLOOKUP(C14,Theory!B17:BJ86,61,FALSE) -> 0 | BU14: =VLOOKUP(C14,Theory!B17:BK86,62,FALSE) -> 0 | BV14: =VLOOKUP(C14,Theory!B17:BL86,63,FALSE) -> 0 | BW14: =VLOOKUP(C14,Theory!B17:BM86,64,FALSE) -> 0 | BX14: =VLOOKUP(C14,Theory!B17:BN86,65,FALSE) -> 0 | BY14: =VLOOKUP(C14,Theory!B17:BO86,66,FALSE) -> 0 | BZ14: =MAX(SUM(BR14:BU14),SUM(BV14:BY14)) -> 2 | CA14: =SUM(AT14,AY14,BH14,BQ14,BZ14) -> 19 | CB14: =VLOOKUP(C14,Theory!B17:BP86,67,FALSE) -> 8 | CC14: =VLOOKUP(C14,Theory!B17:BQ86,68,FALSE) -> 0 | CD14: =VLOOKUP(C14,Theory!B17:BR86,69,FALSE) -> 0 | CE14: =VLOOKUP(C14,Theory!B17:BS86,70,FALSE) -> 0 | CF14: =SUM(CB14:CE14) -> 8 | CG14: =VLOOKUP(C14,Theory!B17:BT86,71,FALSE) -> 8 | CH14: =VLOOKUP(C14,Theory!B17:BU86,72,FALSE) -> 0 | CI14: =VLOOKUP(C14,Theory!B17:BV86,73,FALSE) -> 0 | CJ14: =VLOOKUP(C14,Theory!B17:BW86,74,FALSE) -> 0 | CK14: =SUM(CG14:CJ14) -> 8 | CL14: =VLOOKUP(C14,Theory!B17:BX86,75,FALSE) -> 9 | CM14: =VLOOKUP(C14,Theory!B17:BY86,76,FALSE) -> 0 | CN14: =VLOOKUP(C14,Theory!B17:BZ86,77,FALSE) -> 0 | CO14: =VLOOKUP(C14,Theory!B17:CA86,78,FALSE) -> 0 | CP14: =VLOOKUP(C14,Theory!B17:CB86,79,FALSE) -> 0 | CQ14: =VLOOKUP(C14,Theory!B17:CC86,80,FALSE) -> 0 | CR14: =VLOOKUP(C14,Theory!B17:CD86,81,FALSE) -> 0 | CS14: =VLOOKUP(C14,Theory!B17:CE86,82,FALSE) -> 0 | CT14: =MAX(SUM(CL14:CO14),SUM(CP14:CS14)) -> 9 | CU14: =VLOOKUP(C14,Theory!B17:CF86,83,FALSE) -> 0 | CV14: =VLOOKUP(C14,Theory!B17:CG86,84,FALSE) -> 0 | CW14: =VLOOKUP(C14,Theory!B17:CH86,85,FALSE) -> 0 | CX14: =VLOOKUP(C14,Theory!B17:CI86,86,FALSE) -> 0 | CY14: =VLOOKUP(C14,Theory!B17:CJ86,87,FALSE) -> 9 | CZ14: =VLOOKUP(C14,Theory!B17:CK86,88,FALSE) -> 0 | DA14: =VLOOKUP(C14,Theory!B17:CL86,89,FALSE) -> 0 | DB14: =VLOOKUP(C14,Theory!B17:CM86,90,FALSE) -> 0 | DC14: =MAX(SUM(CU14:CX14),SUM(CY14:DB14)) -> 9 | DD14: =VLOOKUP(C14,Theory!B17:CN86,91,FALSE) -> 0 | DE14: =VLOOKUP(C14,Theory!B17:CO86,92,FALSE) -> 0 | DF14: =VLOOKUP(C14,Theory!B17:CP86,93,FALSE) -> 0 | DG14: =VLOOKUP(C14,Theory!B17:CQ86,94,FALSE) -> 0 | DH14: =VLOOKUP(C14,Theory!B17:CR86,95,FALSE) -> 3 | DI14: =VLOOKUP(C14,Theory!B17:CS86,96,FALSE) -> 0 | DJ14: =VLOOKUP(C14,Theory!B17:CT86,97,FALSE) -> 0 | DK14: =VLOOKUP(C14,Theory!B17:CU86,98,FALSE) -> 0 | DL14: =MAX(SUM(DD14:DG14),SUM(DH14:DK14)) -> 3 | DM14: =SUM(CF14,CK14,CT14,DC14,DL14) -> 37 | DN14: =AO14 -> 29 | DO14: =CA14 -> 19 | DP14: =DM14 -> 37 | DQ14: =ROUND(30*DN14/50,0) -> 17 | DR14: =ROUND(30*DO14/50,0) -> 11 | DS14: =ROUND(30*DP14/50,0) -> 22 | DT14: =ROUND(AVERAGE(DQ14:DS14),0) -> 17 | DU14: =VLOOKUP(C14,Theory!B17:CV86,99,FALSE) -> 7 | DV14: =VLOOKUP(C14,Theory!B17:CW86,100,FALSE) -> 10 | DW14: =SUM(DU14:DV14) -> 17 | DX14: =SUM(DT14:DV14) -> 34 | DY14: =ROUND((30*DX14/50),0) -> 20 | DZ14: =VLOOKUP(C14,Lab!B9:D78,3,FALSE) -> 0 | EA14: =VLOOKUP(C14,Lab!B9:E78,4,FALSE) -> 0 | EB14: =VLOOKUP(C14,Lab!B9:F78,5,FALSE) -> 28 | EC14: =SUM(DZ14:EB14) -> 28 | ED14: =VLOOKUP(C14,Lab!B9:G78,6,FALSE) -> 0 | EE14: =VLOOKUP(C14,Lab!B9:H78,7,FALSE) -> 0 | EF14: 10 | EG14: =SUM(ED14:EF14) -> 10 | EH14: =SUM(EC14,EG14) -> 38 | EI14: =ROUND((20*EH14/50),0) -> 15 | EJ14: =SUM(DY14,EI14) -> 35 | EK14: {=IF(D$8="YES",Lab!K9:K78,Theory!DB17:DB86)} -> 38 | EM14: =VLOOKUP(C14,Theory!B17:DK86,114,FALSE) -> 0 | EN14: =VLOOKUP(C14,Theory!B17:DL86,115,FALSE) -> 0 | EO14: =VLOOKUP(C14,Theory!B17:DM86,116,FALSE) -> 0 | EP14: =VLOOKUP(C14,Theory!B17:DN86,117,FALSE) -> 0 | EQ14: =VLOOKUP(C14,Theory!B17:DO86,118,FALSE) -> 0 | ER14: =VLOOKUP(C14,Theory!B17:DP86,119,FALSE) -> 0 | ES14: =VLOOKUP(C14,Theory!B17:DQ86,120,FALSE) -> 0 | ET14: =SUM(ER14:ES14) -> 0
A15: 2 | B15: =Theory!C18 -> ABHINAND PRAMEESH | C15: =Theory!B18 -> 1DS23AI002 | D15: =VLOOKUP(C15,Theory!B18:D87,3,FALSE) -> 10 | E15: =VLOOKUP(C15,Theory!B18:E87,4,FALSE) -> 0 | F15: =VLOOKUP(C15,Theory!B18:F87,5,FALSE) -> 0 | G15: =VLOOKUP(C15,Theory!B18:G87,6,FALSE) -> 0 | H15: =SUM(D15:G15) -> 10 | I15: =VLOOKUP(C15,Theory!B18:H87,7,FALSE) -> 5 | J15: =VLOOKUP(C15,Theory!B18:I87,8,FALSE) -> 0 | K15: =VLOOKUP(C15,Theory!B18:J87,9,FALSE) -> 0 | L15: =VLOOKUP(C15,Theory!B18:K87,10,FALSE) -> 0 | M15: =SUM(I15:L15) -> 5 | N15: =VLOOKUP(C15,Theory!B18:L87,11,FALSE) -> 8 | O15: =VLOOKUP(C15,Theory!B18:M87,12,FALSE) -> 0 | P15: =VLOOKUP(C15,Theory!B18:N87,13,FALSE) -> 0 | Q15: =VLOOKUP(C15,Theory!B18:O87,14,FALSE) -> 0 | R15: =VLOOKUP(C15,Theory!B18:P87,15,FALSE) -> 0 | S15: =VLOOKUP(C15,Theory!B18:Q87,16,FALSE) -> 0 | T15: =VLOOKUP(C15,Theory!B18:R87,17,FALSE) -> 0 | U15: =VLOOKUP(C15,Theory!B18:S87,18,FALSE) -> 0 | V15: =MAX(SUM(N15:Q15),SUM(R15:U15)) -> 8 | W15: =VLOOKUP(C15,Theory!B18:T87,19,FALSE) -> 0 | X15: =VLOOKUP(C15,Theory!B18:U87,20,FALSE) -> 0 | Y15: =VLOOKUP(C15,Theory!B18:V87,21,FALSE) -> 0 | Z15: =VLOOKUP(C15,Theory!B18:W87,22,FALSE) -> 0 | AA15: =VLOOKUP(C15,Theory!B18:X87,23,FALSE) -> 10 | AB15: =VLOOKUP(C15,Theory!B18:Y87,24,FALSE) -> 0 | AC15: =VLOOKUP(C15,Theory!B18:Z87,25,FALSE) -> 0 | AD15: =VLOOKUP(C15,Theory!B18:AA87,26,FALSE) -> 0 | AE15: =MAX(SUM(W15:Z15),SUM(AA15:AD15)) -> 10 | AF15: =VLOOKUP(C15,Theory!B18:AB87,27,FALSE) -> 0 | AG15: =VLOOKUP(C15,Theory!B18:AC87,28,FALSE) -> 0 | AH15: =VLOOKUP(C15,Theory!B18:AD87,29,FALSE) -> 0 | AI15: =VLOOKUP(C15,Theory!B18:AE87,30,FALSE) -> 0 | AJ15: =VLOOKUP(C15,Theory!B18:AF87,31,FALSE) -> 0 | AK15: =VLOOKUP(C15,Theory!B18:AG87,32,FALSE) -> 0 | AL15: =VLOOKUP(C15,Theory!B18:AH87,33,FALSE) -> 0 | AM15: =VLOOKUP(C15,Theory!B18:AI87,34,FALSE) -> 0 | AN15: =MAX(SUM(AF15:AI15),SUM(AJ15:AM15)) -> 0 | AO15: =SUM(H15,M15,V15,AE15,AN15) -> 33 | AP15: =VLOOKUP(C15,Theory!B18:AJ87,35,FALSE) -> 2 | AQ15: =VLOOKUP(C15,Theory!B18:AK87,36,FALSE) -> 0 | AR15: =VLOOKUP(C15,Theory!B18:AL87,37,FALSE) -> 0 | AS15: =VLOOKUP(C15,Theory!B18:AM87,38,FALSE) -> 0 | AT15: =SUM(AP15:AS15) -> 2 | AU15: =VLOOKUP(C15,Theory!B18:AN87,39,FALSE) -> 6 | AV15: =VLOOKUP(C15,Theory!B18:AO87,40,FALSE) -> 0 | AW15: =VLOOKUP(C15,Theory!B18:AP87,41,FALSE) -> 0 | AX15: =VLOOKUP(C15,Theory!B18:AQ87,42,FALSE) -> 0 | AY15: =SUM(AU15:AX15) -> 6 | AZ15: =VLOOKUP(C15,Theory!B18:AR87,43,FALSE) -> 0 | BA15: =VLOOKUP(C15,Theory!B18:AS87,44,FALSE) -> 0 | BB15: =VLOOKUP(C15,Theory!B18:AT87,45,FALSE) -> 0 | BC15: =VLOOKUP(C15,Theory!B18:AU87,46,FALSE) -> 0 | BD15: =VLOOKUP(C15,Theory!B18:AV87,47,FALSE) -> 8 | BE15: =VLOOKUP(C15,Theory!B18:AW87,48,FALSE) -> 0 | BF15: =VLOOKUP(C15,Theory!B18:AX87,49,FALSE) -> 0 | BG15: =VLOOKUP(C15,Theory!B18:AY87,50,FALSE) -> 0 | BH15: =MAX(SUM(AZ15:BC15),SUM(BD15:BG15)) -> 8 | BI15: =VLOOKUP(C15,Theory!B18:AZ87,51,FALSE) -> 0 | BJ15: =VLOOKUP(C15,Theory!B18:BA87,52,FALSE) -> 0 | BK15: =VLOOKUP(C15,Theory!B18:BB87,53,FALSE) -> 0 | BL15: =VLOOKUP(C15,Theory!B18:BC87,54,FALSE) -> 0 | BM15: =VLOOKUP(C15,Theory!B18:BD87,55,FALSE) -> 2 | BN15: =VLOOKUP(C15,Theory!B18:BE87,56,FALSE) -> 0 | BO15: =VLOOKUP(C15,Theory!B18:BF87,57,FALSE) -> 0 | BP15: =VLOOKUP(C15,Theory!B18:BG87,58,FALSE) -> 0 | BQ15: =MAX(SUM(BI15:BL15),SUM(BM15:BP15)) -> 2 | BR15: =VLOOKUP(C15,Theory!B18:BH87,59,FALSE) -> 0 | BS15: =VLOOKUP(C15,Theory!B18:BI87,60,FALSE) -> 0 | BT15: =VLOOKUP(C15,Theory!B18:BJ87,61,FALSE) -> 0 | BU15: =VLOOKUP(C15,Theory!B18:BK87,62,FALSE) -> 0 | BV15: =VLOOKUP(C15,Theory!B18:BL87,63,FALSE) -> 4 | BW15: =VLOOKUP(C15,Theory!B18:BM87,64,FALSE) -> 0 | BX15: =VLOOKUP(C15,Theory!B18:BN87,65,FALSE) -> 0 | BY15: =VLOOKUP(C15,Theory!B18:BO87,66,FALSE) -> 0 | BZ15: =MAX(SUM(BR15:BU15),SUM(BV15:BY15)) -> 4 | CA15: =SUM(AT15,AY15,BH15,BQ15,BZ15) -> 22 | CB15: =VLOOKUP(C15,Theory!B18:BP87,67,FALSE) -> 9 | CC15: =VLOOKUP(C15,Theory!B18:BQ87,68,FALSE) -> 0 | CD15: =VLOOKUP(C15,Theory!B18:BR87,69,FALSE) -> 0 | CE15: =VLOOKUP(C15,Theory!B18:BS87,70,FALSE) -> 0 | CF15: =SUM(CB15:CE15) -> 9 | CG15: =VLOOKUP(C15,Theory!B18:BT87,71,FALSE) -> 9 | CH15: =VLOOKUP(C15,Theory!B18:BU87,72,FALSE) -> 0 | CI15: =VLOOKUP(C15,Theory!B18:BV87,73,FALSE) -> 0 | CJ15: =VLOOKUP(C15,Theory!B18:BW87,74,FALSE) -> 0 | CK15: =SUM(CG15:CJ15) -> 9 | CL15: =VLOOKUP(C15,Theory!B18:BX87,75,FALSE) -> 10 | CM15: =VLOOKUP(C15,Theory!B18:BY87,76,FALSE) -> 0 | CN15: =VLOOKUP(C15,Theory!B18:BZ87,77,FALSE) -> 0 | CO15: =VLOOKUP(C15,Theory!B18:CA87,78,FALSE) -> 0 | CP15: =VLOOKUP(C15,Theory!B18:CB87,79,FALSE) -> 0 | CQ15: =VLOOKUP(C15,Theory!B18:CC87,80,FALSE) -> 0 | CR15: =VLOOKUP(C15,Theory!B18:CD87,81,FALSE) -> 0 | CS15: =VLOOKUP(C15,Theory!B18:CE87,82,FALSE) -> 0 | CT15: =MAX(SUM(CL15:CO15),SUM(CP15:CS15)) -> 10 | CU15: =VLOOKUP(C15,Theory!B18:CF87,83,FALSE) -> 9 | CV15: =VLOOKUP(C15,Theory!B18:CG87,84,FALSE) -> 0 | CW15: =VLOOKUP(C15,Theory!B18:CH87,85,FALSE) -> 0 | CX15: =VLOOKUP(C15,Theory!B18:CI87,86,FALSE) -> 0 | CY15: =VLOOKUP(C15,Theory!B18:CJ87,87,FALSE) -> 0 | CZ15: =VLOOKUP(C15,Theory!B18:CK87,88,FALSE) -> 0 | DA15: =VLOOKUP(C15,Theory!B18:CL87,89,FALSE) -> 0 | DB15: =VLOOKUP(C15,Theory!B18:CM87,90,FALSE) -> 0 | DC15: =MAX(SUM(CU15:CX15),SUM(CY15:DB15)) -> 9 | DD15: =VLOOKUP(C15,Theory!B18:CN87,91,FALSE) -> 10 | DE15: =VLOOKUP(C15,Theory!B18:CO87,92,FALSE) -> 0 | DF15: =VLOOKUP(C15,Theory!B18:CP87,93,FALSE) -> 0 | DG15: =VLOOKUP(C15,Theory!B18:CQ87,94,FALSE) -> 0 | DH15: =VLOOKUP(C15,Theory!B18:CR87,95,FALSE) -> 0 | DI15: =VLOOKUP(C15,Theory!B18:CS87,96,FALSE) -> 0 | DJ15: =VLOOKUP(C15,Theory!B18:CT87,97,FALSE) -> 0 | DK15: =VLOOKUP(C15,Theory!B18:CU87,98,FALSE) -> 0 | DL15: =MAX(SUM(DD15:DG15),SUM(DH15:DK15)) -> 10 | DM15: =SUM(CF15,CK15,CT15,DC15,DL15) -> 47 | DN15: =AO15 -> 33 | DO15: =CA15 -> 22 | DP15: =DM15 -> 47 | DQ15: =ROUND(30*DN15/50,0) -> 20 | DR15: =ROUND(30*DO15/50,0) -> 13 | DS15: =ROUND(30*DP15/50,0) -> 28 | DT15: =ROUND(AVERAGE(DQ15:DS15),0) -> 20 | DU15: =VLOOKUP(C15,Theory!B18:CV87,99,FALSE) -> 6 | DV15: =VLOOKUP(C15,Theory!B18:CW87,100,FALSE) -> 10 | DW15: =SUM(DU15:DV15) -> 16 | DX15: =SUM(DT15:DV15) -> 36 | DY15: =ROUND((30*DX15/50),0) -> 22 | DZ15: =VLOOKUP(C15,Lab!B10:D79,3,FALSE) -> 0 | EA15: =VLOOKUP(C15,Lab!B10:E79,4,FALSE) -> 0 | EB15: =VLOOKUP(C15,Lab!B10:F79,5,FALSE) -> 30 | EC15: =SUM(DZ15:EB15) -> 30 | ED15: =VLOOKUP(C15,Lab!B10:G79,6,FALSE) -> 0 | EE15: =VLOOKUP(C15,Lab!B10:H79,7,FALSE) -> 0 | EF15: =VLOOKUP(C15,Lab!B10:I79,8,FALSE) -> 20 | EG15: =SUM(ED15:EF15) -> 20 | EH15: =SUM(EC15,EG15) -> 50 | EI15: =ROUND((20*EH15/50),0) -> 20 | EJ15: =SUM(DY15,EI15) -> 42 | EK15: 38.5 | EM15: =VLOOKUP(C15,Theory!B18:DK87,114,FALSE) -> 0 | EN15: =VLOOKUP(C15,Theory!B18:DL87,115,FALSE) -> 0 | EO15: =VLOOKUP(C15,Theory!B18:DM87,116,FALSE) -> 0 | EP15: =VLOOKUP(C15,Theory!B18:DN87,117,FALSE) -> 0 | EQ15: =VLOOKUP(C15,Theory!B18:DO87,118,FALSE) -> 0 | ER15: =VLOOKUP(C15,Theory!B18:DP87,119,FALSE) -> 0 | ES15: =VLOOKUP(C15,Theory!B18:DQ87,120,FALSE) -> 0 | ET15: =SUM(ER15:ES15) -> 0
