Workbook

Sheet Theory
A1: DAYANANDA SAGAR COLLEGE OF ENGINEERING, BANGALORE-560 111
A2: DEPARTMENT OF ARTIFICIAL INTELLEGENCE & MACHINE LEARNING
A4: Academic Year : 2023 -24 | D4: Scheme :2021-25 | Q4: Semester : 6th
A5: COURSE CODE : 21AI643
A6: COURSE TITLE :IoT & 5G
A7: STAND ALONE THEORY | D7: YES
A8: STAND ALONE LAB | D8: NO
A9: IPCC | D9: NO
C11: Course Outcome Attainment Calculation
C12: COs mapped | D12: 0,1 | H12: 0,1 | L12: 0,1 | P12: 0,1 | T12: 0,1 | X12: 0,1 | AB12: 0,1 | AF12: 0,1 | AJ12: 0,4 | AN12: 0,4 | AO12: 0,4 | AR12: 0,2 | AV12: 0,2 | AZ12: 0,4 | BD12: 0,4 | BH12: 0,4 | BL12: 0,4 | BP12: 0,3 | BT12: 0,4 | BX12: 0,3 | CB12: 0,3 | CF12: 0,3 | CJ12: 0,3 | CN12: 0,4 | CR12: 0,4 | CV12: 0,1,2,3,4 | CW12: 0,1,2,3,4 | DL12: ENTER ATTENDANCE MANUALLY FOR CSV FILE
D13: Test 1 | AJ13: Test 2 | BP13: Test 3 | CV13: AAT | CW13: QUIZ | DL13: STAND ALONE THEORY ATTENDANCE | DM13: STAND ALONE THEORY ATTENDANCE | DN13: STAND ALONE THEORY ATTENDANCE | DO13: STAND ALONE THEORY ATTENDANCE | DP13: STAND ALONE LAB ATTENDANCE | DQ13: IPCC THEORY ATTENDANCE | DR13: IPCC LAB ATTENDANCE | DS13: IPCC TOTAL ATTENDANCE
C14: Maximum Marks | D14: 10 | H14: 10 | L14: 10 | P14: 10 | T14: 10 | X14: 10 | AB14: 10 | AF14: 10 | AJ14: 10 | AN14: 5 | AO14: 5 | AR14: 10 | AV14: 10 | AZ14: 10 | BD14: 10 | BH14: 10 | BL14: 10 | BP14: 10 | BT14: 10 | BX14: 10 | CB14: 10 | CF14: 10 | CJ14: 10 | CN14: 10 | CR14: 10 | CV14: 10 | CW14: 10 | CX14: 50 | CY14: 50 | CZ14: 50 | DA14: 50 | DB14: 100 | DC14: 50 | DG14: CIA | DJ14: SEE | DL14: CREDIT-1 | DM14: CREDIT-2 | DN14: CREDIT-3 | DO14: CREDIT-4 | DP14: CREDIT-1 | DQ14: CREDIT-4
C15: Marks to reach Performance (60% and above of Max. Marks) | D15: 6 | H15: 6 | L15: 6 | P15: 6 | T15: 6 | X15: 6 | AB15: 6 | AF15: 6 | AJ15: 6 | AN15: 3 | AO15: 3 | AR15: 6 | AV15: 6 | AZ15: 6 | BD15: 6 | BH15: 6 | BL15: 6 | BP15: 6 | BT15: 6 | BX15: 6 | CB15: 6 | CF15: 6 | CJ15: 6 | CN15: 6 | CR15: 6 | CV15: 6 | CW15: 6 | CX15: 30 | CY15: 30 | CZ15: 30 | DA15: 30 | DB15: 60 | DC15: 30 | DG15: ='CIA MARKS'!DX12 -> STAND ALONE THEORY | DH15: ='CIA MARKS'!EH12 -> STAND ALONE LAB | DI15: ='CIA MARKS'!EJ12 -> IPCC | DJ15: ='CIA MARKS'!EK12 -> SEE | DL15: ATTND (11/12) | DM15: ATTND (11/24) | DN15: ATTND (34/40) | DO15: ATTND (45/52) | DP15: ATTND (11/12) | DQ15: ATT-THEORY (34/40) | DR15: ATT-LAB (11/12)
A16: Sl No. | B16: USN | C16: STUDENT NAME | D16: Q1A | E16: Q1B | F16: Q1C | G16: Q1D | H16: Q2A | I16: Q2B | J16: Q2C | K16: Q2D | L16: Q3A | M16: Q3B | N16: Q3C | O16: Q3D | P16: Q4A | Q16: Q4B | R16: Q4C | S16: Q4D | T16: Q5A | U16: Q5B | V16: Q5C | W16: Q5D | X16: Q6A | Y16: Q6B | Z16: Q6C | AA16: Q6D | AB16: Q7A | AC16: Q7B | AD16: Q7C | AE16: Q7D | AF16: Q8A | AG16: Q8B | AH16: Q8C | AI16: Q8D | AJ16: Q1A | AK16: Q1A | AL16: Q1C | AM16: Q1D | AN16: Q2A | AO16: Q2A | AP16: Q2C | AQ16: Q2D | AR16: Q3A | AS16: Q3B | AT16: Q3C | AU16: Q3D | AV16: Q4A | AW16: Q4B | AX16: Q4C | AY16: Q4D | AZ16: Q5A | BA16: Q5B | BB16: Q5C | BC16: Q5D | BD16: Q6A | BE16: Q6B | BF16: Q6C | BG16: Q6D | BH16: Q7A | BI16: Q7B | BJ16: Q7C | BK16: Q7D | BL16: Q8A | BM16: Q8B | BN16: Q8C | BO16: Q8D | BP16: Q1A | BQ16: Q1B | BR16: Q1C | BS16: Q1D | BT16: Q2A | BU16: Q2B | BV16: Q2C | BW16: Q2D | BX16: Q3A | BY16: Q3B | BZ16: Q3C | CA16: Q3D | CB16: Q4A | CC16: Q4B | CD16: Q4C | CE16: Q4D | CF16: Q5A | CG16: Q5B | CH16: Q5C | CI16: Q5D | CJ16: Q6A | CK16: Q6B | CL16: Q6C | CM16: Q6D | CN16: Q7A | CO16: Q7B | CP16: Q7C | CQ16: Q7D | CR16: Q8A | CS16: Q8B | CT16: Q8C | CU16: Q8D | CV16: Q1-20 | CW16: Q1-20 | CX16: Total Test1 | CY16: Total Test 2 | CZ16: Total Test 3 | DA16: Final CIA | DB16: Final SEE MARKS | DC16: Final SEE MARKS | DE16: Final SEE Grade | DG16: ='CIA MARKS'!DX13 -> 50 | DH16: ='CIA MARKS'!EH13 -> 0 | DI16: ='CIA MARKS'!EJ13 -> 30 | DJ16: ='CIA MARKS'!EK13 -> 50 | DL16: 12 | DM16: 24 | DN16: 40 | DO16: 52 | DP16: 12 | DQ16: 40 | DR16: 12 | DS16: =SUM(DQ16:DR16) -> 52
A17: 1 | B17: 1DS21AI001 | C17: ADITHYA N AWATI | D17: 9 | H17: 8 | L17: 8 | T17: 8 | AB17: 9 | AJ17: 9 | AN17: 9 | AR17: 9 | AZ17: 8 | BH17: 10 | BP17: 7 | BT17: 9 | BX17: 10 | CF17: 9 | CN17: 8 | CV17: 10 | CW17: 5 | DA17: 41 | DB17: 83 | DC17: 42 | DE17: A+ | DG17: =IF(D$7="YES",'CIA MARKS'!DX14,"") -> 41 | DH17: =IF(D$8="YES",'CIA MARKS'!EH14,"") | DI17: =IF(D$9="YES",'CIA MARKS'!EJ14,"") | DJ17: =IF(Theory!D$7="YES",DC17, IF(Theory!D$8="YES",Lab!K9, IF(Theory!D$9="YES",DC17,""))) -> 42 | DS17: =SUM(DQ17:DR17) -> 0
A18: 2 | B18: 1DS21AI002 | C18: AMIT A | D18: 9 | H18: 9 | L18: 10 | T18: 10 | AB18: 10 | AJ18: 9 | AN18: 9 | AR18: 10 | AZ18: 8 | BH18: 9 | BP18: 10 | BT18: 9 | BX18: 9 | CF18: 10 | CR18: 10 | CV18: 10 | CW18: 10 | DA18: 48 | DB18: 88 | DC18: 40 | DE18: A+ | DG18: =IF(D$7="YES",'CIA MARKS'!DX15,"") -> 48 | DH18: =IF(D$8="YES",'CIA MARKS'!EH15,"") | DI18: =IF(D$9="YES",'CIA MARKS'!EJ15,"") | DJ18: =IF(Theory!D$7="YES",DC18, IF(Theory!D$8="YES",Lab!K10, IF(Theory!D$9="YES",DC18,""))) -> 40 | DS18: =SUM(DQ18:DR18) -> 0
A19: 3 | B19: 1DS21AI005 | C19: ANKUSH G | D19: 7 | H19: 8 | P19: 9 | X19: 9 | AB19: 10 | AJ19: 9 | AN19: 10 | AR19: 10 | AZ19: 8 | BH19: 10 | BP19: 9 | BT19: 9 | CB19: 10 | CF19: 10 | CN19: 9 | CV19: 10 | CW19: 10 | DA19: 47 | DB19: 89 | DC19: 42 | DE19: A+ | DG19: =IF(D$7="YES",'CIA MARKS'!DX16,"") -> 47 | DH19: =IF(D$8="YES",'CIA MARKS'!EH16,"") | DI19: =IF(D$9="YES",'CIA MARKS'!EJ16,"") | DJ19: =IF(Theory!D$7="YES",DC19, IF(Theory!D$8="YES",Lab!K11, IF(Theory!D$9="YES",DC19,""))) -> 42 | DS19: =SUM(DQ19:DR19) -> 0
A20: 4 | B20: 1DS21AI006 | C20: ARYAMAN SAXENA | D20: 6 | H20: 5 | L20: 10 | X20: 7 | AB20: 7 | BP20: 5 | BT20: 8 | BX20: 9 | CF20: 10 | CN20: 8 | CV20: 10 | CW20: 10 | DA20: 35 | DB20: 76 | DC20: 41 | DE20: A | DG20: =IF(D$7="YES",'CIA MARKS'!DX17,"") -> 35 | DH20: =IF(D$8="YES",'CIA MARKS'!EH17,"") | DI20: =IF(D$9="YES",'CIA MARKS'!EJ17,"") | DJ20: =IF(Theory!D$7="YES",DC20, IF(Theory!D$8="YES",Lab!K12, IF(Theory!D$9="YES",DC20,""))) -> 41 | DS20: =SUM(DQ20:DR20) -> 0
A21: 5 | B21: 1DS21AI007 | C21: ASHWIN SAI G | D21: 7 | P21: 5 | X21: 4 | AB21: 4 | AN21: 2 | AR21: 6 | AV21: 1 | AZ21: 2 | BL21: 5 | BP21: 6 | BT21: 1 | BX21: 6 | CB21: 7 | CR21: 6 | CV21: 10 | CW21: 10 | DA21: 32 | DB21: 53 | DC21: 21 | DE21: C | DG21: =IF(D$7="YES",'CIA MARKS'!DX18,"") -> 31 | DH21: =IF(D$8="YES",'CIA MARKS'!EH18,"") | DI21: =IF(D$9="YES",'CIA MARKS'!EJ18,"") | DJ21: =IF(Theory!D$7="YES",DC21, IF(Theory!D$8="YES",Lab!K13, IF(Theory!D$9="YES",DC21,""))) -> 21 | DS21: =SUM(DQ21:DR21) -> 0
A22: 6 | B22: 1DS21AI009 | C22: BHARGAVI K | D22: 8 | H22: 6 | L22: 10 | X22: 9 | AF22: 9 | AJ22: 10 | AN22: 9 | AR22: 9 | AZ22: 7 | BH22: 8 | BP22: 9 | BT22: 7 | CB22: 10 | CF22: 10 | CN22: 9 | CV22: 10 | CW22: 10 | DA22: 46 | DB22: 89 | DC22: 43 | DE22: A+ | DG22: =IF(D$7="YES",'CIA MARKS'!DX19,"") -> 46 | DH22: =IF(D$8="YES",'CIA MARKS'!EH19,"") | DI22: =IF(D$9="YES",'CIA MARKS'!EJ19,"") | DJ22: =IF(Theory!D$7="YES",DC22, IF(Theory!D$8="YES",Lab!K14, IF(Theory!D$9="YES",DC22,""))) -> 43 | DS22: =SUM(DQ22:DR22) -> 0
A23: 7 | B23: 1DS21AI014 | C23: DARSHAN R | D23: 8 | H23: 7 | L23: 8 | T23: 6 | AJ23: 5 | AN23: 6 | AR23: 9 | BD23: 5 | BL23: 8 | BP23: 9 | BT23: 7 | BX23: 9 | CJ23: 8 | CR23: 9 | CV23: 10 | CW23: 10 | DA23: 41 | DB23: 76 | DC23: 35 | DE23: A | DG23: =IF(D$7="YES",'CIA MARKS'!DX20,"") -> 41 | DH23: =IF(D$8="YES",'CIA MARKS'!EH20,"") | DI23: =IF(D$9="YES",'CIA MARKS'!EJ20,"") | DJ23: =IF(Theory!D$7="YES",DC23, IF(Theory!D$8="YES",Lab!K15, IF(Theory!D$9="YES",DC23,""))) -> 35 | DS23: =SUM(DQ23:DR23) -> 0
A24: 8 | B24: 1DS21AI017 | C24: FATIMA ANEES MULLA | D24: 6 | H24: 7 | L24: 9 | X24: 9 | AF24: 8 | AJ24: 7 | AN24: 8 | AR24: 9 | AZ24: 7 | BH24: 9 | BP24: 9 | BT24: 8 | CB24: 9 | CF24: 9 | CR24: 10 | CV24: 10 | CW24: 10 | DA24: 45 | DB24: 90 | DC24: 45 | DE24: o | DG24: =IF(D$7="YES",'CIA MARKS'!DX21,"") -> 45 | DH24: =IF(D$8="YES",'CIA MARKS'!EH21,"") | DI24: =IF(D$9="YES",'CIA MARKS'!EJ21,"") | DJ24: =IF(Theory!D$7="YES",DC24, IF(Theory!D$8="YES",Lab!K16, IF(Theory!D$9="YES",DC24,""))) -> 45 | DS24: =SUM(DQ24:DR24) -> 0
A25: 9 | B25: 1DS21AI019 | C25: HARIKRISHNA M | D25: 5 | H25: 5 | L25: 5 | T25: 4 | AB25: 4 | AJ25: 3 | AN25: 4 | AR25: 7 | BD25: 5 | BL25: 5 | BP25: 7 | BT25: 6 | BX25: 7 | CJ25: 6 | CN25: 5 | CV25: 10 | CW25: 10 | DA25: 36 | DB25: 69 | DC25: 33 | DE25: B+ | DG25: =IF(D$7="YES",'CIA MARKS'!DX22,"") -> 36 | DH25: =IF(D$8="YES",'CIA MARKS'!EH22,"") | DI25: =IF(D$9="YES",'CIA MARKS'!EJ22,"") | DJ25: =IF(Theory!D$7="YES",DC25, IF(Theory!D$8="YES",Lab!K17, IF(Theory!D$9="YES",DC25,""))) -> 33 | DS25: =SUM(DQ25:DR25) -> 0
A26: 10 | B26: 1DS21AI020 | C26: HARSHITHA B | AN26: 7 | AR26: 9 | BD26: 7 | BH26: 8 | BT26: 3 | BX26: 8 | CF26: 8 | CN26: 7 | CV26: 10 | CW26: 10 | DA26: 32 | DB26: 65 | DC26: 33 | DE26: B+ | DG26: =IF(D$7="YES",'CIA MARKS'!DX23,"") -> 32 | DH26: =IF(D$8="YES",'CIA MARKS'!EH23,"") | DI26: =IF(D$9="YES",'CIA MARKS'!EJ23,"") | DJ26: =IF(Theory!D$7="YES",DC26, IF(Theory!D$8="YES",Lab!K18, IF(Theory!D$9="YES",DC26,""))) -> 33 | DS26: =SUM(DQ26:DR26) -> 0
A27: 11 | B27: 1DS21AI021 | C27: HARSHITHA S | D27: 8 | H27: 9 | L27: 8 | T27: 7 | AB27: 9 | AN27: 9 | AR27: 10 | AZ27: 8 | BH27: 9 | BP27: 9 | BT27: 8 | CB27: 8 | CF27: 10 | CR27: 9 | CV27: 10 | CW27: 10 | DA27: 44 | DB27: 85 | DC27: 41 | DE27: A+ | DG27: =IF(D$7="YES",'CIA MARKS'!DX24,"") -> 44 | DH27: =IF(D$8="YES",'CIA MARKS'!EH24,"") | DI27: =IF(D$9="YES",'CIA MARKS'!EJ24,"") | DJ27: =IF(Theory!D$7="YES",DC27, IF(Theory!D$8="YES",Lab!K19, IF(Theory!D$9="YES",DC27,""))) -> 41 | DS27: =SUM(DQ27:DR27) -> 0
A28: 12 | B28: 1DS21AI023 | C28: HITHA N | D28: 8 | H28: 8 | L28: 10 | T28: 8 | AB28: 10 | AJ28: 9 | AN28: 9 | AR28: 10 | AZ28: 8 | BH28: 10 | BP28: 10 | BT28: 10 | CB28: 10 | CF28: 10 | CR28: 10 | CV28: 10 | CW28: 10 | DA28: 48 | DB28: 93 | DC28: 45 | DE28: O | DG28: =IF(D$7="YES",'CIA MARKS'!DX25,"") -> 48 | DH28: =IF(D$8="YES",'CIA MARKS'!EH25,"") | DI28: =IF(D$9="YES",'CIA MARKS'!EJ25,"") | DJ28: =IF(Theory!D$7="YES",DC28, IF(Theory!D$8="YES",Lab!K20, IF(Theory!D$9="YES",DC28,""))) -> 45 | DS28: =SUM(DQ28:DR28) -> 0
A29: 13 | B29: 1DS21AI026 | C29: KAASHIF MERAJ | D29: 2 | H29: 2 | P29: 3 | X29: 4 | AF29: 4 | AJ29: 7 | AN29: 6 | AR29: 9 | BL29: 5 | BP29: 2 | BT29: 8 | BX29: 7 | CJ29: 7 | CN29: 7 | CV29: 10 | CW29: 10 | DA29: 35 | DB29: 62 | DC29: 27 | DE29: B+ | DG29: =IF(D$7="YES",'CIA MARKS'!DX26,"") -> 35 | DH29: =IF(D$8="YES",'CIA MARKS'!EH26,"") | DI29: =IF(D$9="YES",'CIA MARKS'!EJ26,"") | DJ29: =IF(Theory!D$7="YES",DC29, IF(Theory!D$8="YES",Lab!K21, IF(Theory!D$9="YES",DC29,""))) -> 27 | DS29: =SUM(DQ29:DR29) -> 0
A30: 14 | B30: 1DS21AI027 | C30: KOTIREDDY CHARAN SIMHA REDDY | D30: 5 | H30: 6 | L30: 7 | T30: 5 | AB30: 7 | AJ30: 6 | AN30: 5 | AR30: 8 | BD30: 5 | BL30: 6 | BP30: 5 | BT30: 7 | CB30: 7 | CF30: 6 | CR30: 6 | CV30: 10 | CW30: 10 | DA30: 38 | DB30: 70 | DC30: 32 | DE30: A | DG30: =IF(D$7="YES",'CIA MARKS'!DX27,"") -> 38 | DH30: =IF(D$8="YES",'CIA MARKS'!EH27,"") | DI30: =IF(D$9="YES",'CIA MARKS'!EJ27,"") | DJ30: =IF(Theory!D$7="YES",DC30, IF(Theory!D$8="YES",Lab!K22, IF(Theory!D$9="YES",DC30,""))) -> 32 | DS30: =SUM(DQ30:DR30) -> 0
A31: 15 | B31: 1DS21AI028 | C31: KRUTIKA R SINNUR | D31: 8 | H31: 7 | L31: 10 | T31: 10 | AB31: 9 | AJ31: 10 | AN31: 10 | AR31: 10 | AZ31: 8 | BH31: 10 | BP31: 9 | BT31: 9 | BX31: 10 | CF31: 10 | CR31: 9 | CV31: 10 | CW31: 10 | DA31: 48 | DB31: 86 | DC31: 38 | DE31: A+ | DG31: =IF(D$7="YES",'CIA MARKS'!DX28,"") -> 48 | DH31: =IF(D$8="YES",'CIA MARKS'!EH28,"") | DI31: =IF(D$9="YES",'CIA MARKS'!EJ28,"") | DJ31: =IF(Theory!D$7="YES",DC31, IF(Theory!D$8="YES",Lab!K23, IF(Theory!D$9="YES",DC31,""))) -> 38 | DS31: =SUM(DQ31:DR31) -> 0
A32: 16 | B32: 1DS21AI030 | C32: MANAS KALRA | D32: 10 | H32: 7 | L32: 5 | T32: 5 | AB32: 8 | AJ32: 7 | AN32: 7 | AR32: 8 | AZ32: 7 | BD32: 8 | BP32: 8 | BT32: 8 | BX32: 9 | CJ32: 9 | CR32: 8 | CV32: 10 | CW32: 10 | DA32: 43 | DB32: 84 | DC32: 41 | DE32: A+ | DG32: =IF(D$7="YES",'CIA MARKS'!DX29,"") -> 41 | DH32: =IF(D$8="YES",'CIA MARKS'!EH29,"") | DI32: =IF(D$9="YES",'CIA MARKS'!EJ29,"") | DJ32: =IF(Theory!D$7="YES",DC32, IF(Theory!D$8="YES",Lab!K24, IF(Theory!D$9="YES",DC32,""))) -> 41 | DS32: =SUM(DQ32:DR32) -> 0
A33: 17 | B33: 1DS21AI031 | C33: MANASVINI T | D33: 7 | H33: 8 | L33: 4 | X33: 7 | AF33: 8 | AJ33: 7 | AN33: 8 | AR33: 9 | AZ33: 8 | BH33: 10 | BP33: 9 | BT33: 8 | BX33: 9 | CF33: 10 | CR33: 8 | CV33: 10 | CW33: 10 | DA33: 44 | DB33: 82 | DC33: 38 | DE33: A+ | DG33: =IF(D$7="YES",'CIA MARKS'!DX30,"") -> 44 | DH33: =IF(D$8="YES",'CIA MARKS'!EH30,"") | DI33: =IF(D$9="YES",'CIA MARKS'!EJ30,"") | DJ33: =IF(Theory!D$7="YES",DC33, IF(Theory!D$8="YES",Lab!K25, IF(Theory!D$9="YES",DC33,""))) -> 38 | DS33: =SUM(DQ33:DR33) -> 0
A34: 18 | B34: 1DS21AI032 | C34: MESHANK BANSAL | D34: 5 | H34: 5 | P34: 7 | T34: 6 | AB34: 7 | AJ34: 7 | AN34: 5 | AR34: 8 | BD34: 7 | BH34: 8 | BP34: 5 | BT34: 9 | CB34: 8 | CJ34: 8 | CN34: 7 | CV34: 10 | CW34: 10 | DA34: 40 | DB34: 70 | DC34: 30 | DE34: A | DG34: =IF(D$7="YES",'CIA MARKS'!DX31,"") -> 40 | DH34: =IF(D$8="YES",'CIA MARKS'!EH31,"") | DI34: =IF(D$9="YES",'CIA MARKS'!EJ31,"") | DJ34: =IF(Theory!D$7="YES",DC34, IF(Theory!D$8="YES",Lab!K26, IF(Theory!D$9="YES",DC34,""))) -> 30 | DS34: =SUM(DQ34:DR34) -> 0
A35: 19 | B35: 1DS21AI034 | C35: MONICA K C | D35: 10 | H35: 9 | L35: 8 | T35: 9 | AB35: 8 | AJ35: 10 | AN35: 10 | AV35: 9 | AZ35: 8 | BH35: 10 | BP35: 9 | BT35: 9 | CB35: 9 | CJ35: 8 | CR35: 9 | CV35: 10 | CW35: 10 | DA35: 47 | DB35: 90 | DC35: 43 | DE35: O | DG35: =IF(D$7="YES",'CIA MARKS'!DX32,"") -> 47 | DH35: =IF(D$8="YES",'CIA MARKS'!EH32,"") | DI35: =IF(D$9="YES",'CIA MARKS'!EJ32,"") | DJ35: =IF(Theory!D$7="YES",DC35, IF(Theory!D$8="YES",Lab!K27, IF(Theory!D$9="YES",DC35,""))) -> 43 | DS35: =SUM(DQ35:DR35) -> 0
A36: 20 | B36: 1DS21AI035 | C36: NANDITHA K G | D36: 8 | H36: 7 | P36: 6 | T36: 7 | AB36: 10 | AJ36: 7 | AN36: 6 | AR36: 9 | AZ36: 8 | BH36: 9 | BT36: 9 | BX36: 8 | CF36: 10 | CR36: 9 | CV36: 10 | CW36: 10 | DA36: 43 | DB36: 85 | DC36: 42 | DE36: A+ | DG36: =IF(D$7="YES",'CIA MARKS'!DX33,"") -> 43 | DH36: =IF(D$8="YES",'CIA MARKS'!EH33,"") | DI36: =IF(D$9="YES",'CIA MARKS'!EJ33,"") | DJ36: =IF(Theory!D$7="YES",DC36, IF(Theory!D$8="YES",Lab!K28, IF(Theory!D$9="YES",DC36,""))) -> 42 | DS36: =SUM(DQ36:DR36) -> 0
A37: 21 | B37: 1DS21AI038 | C37: PRAJWAL K | AJ37: 8 | AN37: 7 | AR37: 9 | AZ37: 8 | BH37: 8 | BP37: 8 | BT37: 8 | BX37: 9 | CJ37: 8 | CN37: 7 | CV37: 10 | CW37: 10 | DA37: 36 | DB37: 76 | DC37: 40 | DE37: A | DG37: =IF(D$7="YES",'CIA MARKS'!DX34,"") -> 36 | DH37: =IF(D$8="YES",'CIA MARKS'!EH34,"") | DI37: =IF(D$9="YES",'CIA MARKS'!EJ34,"") | DJ37: =IF(Theory!D$7="YES",DC37, IF(Theory!D$8="YES",Lab!K29, IF(Theory!D$9="YES",DC37,""))) -> 40 | DS37: =SUM(DQ37:DR37) -> 0
A38: 22 | B38: 1DS21AI039 | C38: PRAKRITI SINGH | D38: 7 | H38: 5 | L38: 6 | T38: 7 | AB38: 6 | AJ38: 6 | AN38: 6 | AR38: 9 | AZ38: 7 | BH38: 8 | BP38: 7 | BT38: 1 | CB38: 7 | CJ38: 7 | CN38: 6 | CV38: 10 | CW38: 10 | DA38: 39 | DB38: 80 | DC38: 41 | DE38: A+ | DG38: =IF(D$7="YES",'CIA MARKS'!DX35,"") -> 39 | DH38: =IF(D$8="YES",'CIA MARKS'!EH35,"") | DI38: =IF(D$9="YES",'CIA MARKS'!EJ35,"") | DJ38: =IF(Theory!D$7="YES",DC38, IF(Theory!D$8="YES",Lab!K30, IF(Theory!D$9="YES",DC38,""))) -> 41 | DS38: =SUM(DQ38:DR38) -> 0
A39: 23 | B39: 1DS21AI040 | C39: PRERANA S B | H39: 8 | P39: 5 | X39: 8 | AB39: 8 | AJ39: 6 | AN39: 8 | AV39: 5 | AZ39: 8 | BH39: 9 | BP39: 8 | CB39: 8 | CF39: 7 | CN39: 7 | CV39: 10 | CW39: 10 | DA39: 39 | DB39: 79 | DC39: 40 | DE39: A | DG39: =IF(D$7="YES",'CIA MARKS'!DX36,"") -> 39 | DH39: =IF(D$8="YES",'CIA MARKS'!EH36,"") | DI39: =IF(D$9="YES",'CIA MARKS'!EJ36,"") | DJ39: =IF(Theory!D$7="YES",DC39, IF(Theory!D$8="YES",Lab!K31, IF(Theory!D$9="YES",DC39,""))) -> 40 | DS39: =SUM(DQ39:DR39) -> 0
A40: 24 | B40: 1DS21AI041 | C40: RADHIKA MITTAL | D40: 6 | H40: 9 | L40: 7 | T40: 8 | AF40: 10 | AJ40: 10 | AN40: 10 | AR40: 10 | AZ40: 8 | BH40: 10 | BP40: 8 | BT40: 9 | BX40: 10 | CF40: 9 | CN40: 10 | CV40: 10 | CW40: 10 | DA40: 47 | DB40: 89 | DC40: 42 | DE40: A+ | DG40: =IF(D$7="YES",'CIA MARKS'!DX37,"") -> 47 | DH40: =IF(D$8="YES",'CIA MARKS'!EH37,"") | DI40: =IF(D$9="YES",'CIA MARKS'!EJ37,"") | DJ40: =IF(Theory!D$7="YES",DC40, IF(Theory!D$8="YES",Lab!K32, IF(Theory!D$9="YES",DC40,""))) -> 42 | DS40: =SUM(DQ40:DR40) -> 0
A41: 25 | B41: 1DS21AI044 | C41: S UDAY KUMAR | D41: 1 | H41: 8 | L41: 10 | T41: 10 | AB41: 5 | AJ41: 6 | AN41: 5 | AR41: 8 | AZ41: 8 | BL41: 7 | BP41: 6 | BT41: 5 | BX41: 5 | CJ41: 9 | CR41: 6 | CV41: 10 | CW41: 10 | DA41: 40 | DB41: 81 | DC41: 41 | DE41: A+ | DG41: =IF(D$7="YES",'CIA MARKS'!DX38,"") -> 40 | DH41: =IF(D$8="YES",'CIA MARKS'!EH38,"") | DI41: =IF(D$9="YES",'CIA MARKS'!EJ38,"") | DJ41: =IF(Theory!D$7="YES",DC41, IF(Theory!D$8="YES",Lab!K33, IF(Theory!D$9="YES",DC41,""))) -> 41 | DS41: =SUM(DQ41:DR41) -> 0
A42: 26 | B42: 1DS21AI045 | C42: SHAMS AARIZE SIDDIQUE | D42: 7 | H42: 8 | L42: 8 | T42: 8 | AB42: 9 | AJ42: 6 | AN42: 10 | AR42: 9 | AZ42: 8 | BH42: 9 | BP42: 8 | BT42: 8 | CB42: 7 | CJ42: 9 | CN42: 7 | CV42: 10 | CW42: 10 | DA42: 44 | DB42: 87 | DC42: 43 | DE42: A+ | DG42: =IF(D$7="YES",'CIA MARKS'!DX39,"") -> 44 | DH42: =IF(D$8="YES",'CIA MARKS'!EH39,"") | DI42: =IF(D$9="YES",'CIA MARKS'!EJ39,"") | DJ42: =IF(Theory!D$7="YES",DC42, IF(Theory!D$8="YES",Lab!K34, IF(Theory!D$9="YES",DC42,""))) -> 43 | DS42: =SUM(DQ42:DR42) -> 0
...

Sheet Lab
D3: Continuous Internal Evaluation-(CIE) | G3: Test | J3: FINAL LAB MARKS
C4: POs Mapped
C5: COs mapped
C6: Maximum Marks
C7: Marks to reach Performance (60% and above of Max. Marks) | D7: =0.6*D6 -> 0 | E7: =0.6*E6 -> 0 | F7: =0.6*F6 -> 0 | G7: =0.6*G6 -> 0 | H7: =0.6*H6 -> 0 | I7: =0.6*I6 -> 0 | J7: =0.6*J6 -> 0
A8: Sl No. | B8: USN | C8: Names | D8: COMPONENT-1 | G8: COMPONENT-2 | J8: CIA | K8: SEE
A9: 1 | B9: =Theory!B17 -> 1DS21AI001 | C9: =Theory!C17 -> ADITHYA N AWATI
A10: 2 | B10: =Theory!B18 -> 1DS21AI002 | C10: =Theory!C18 -> AMIT A
A11: 3 | B11: =Theory!B19 -> 1DS21AI005 | C11: =Theory!C19 -> ANKUSH G
A12: 4 | B12: =Theory!B20 -> 1DS21AI006 | C12: =Theory!C20 -> ARYAMAN SAXENA
A13: 5 | B13: =Theory!B21 -> 1DS21AI007 | C13: =Theory!C21 -> ASHWIN SAI G
A14: 6 | B14: =Theory!B22 -> 1DS21AI009 | C14: =Theory!C22 -> BHARGAVI K
A15: 7 | B15: =Theory!B23 -> 1DS21AI014 | C15: =Theory!C23 -> DARSHAN R
A16: 8 | B16: =Theory!B24 -> 1DS21AI017 | C16: =Theory!C24 -> FATIMA ANEES MULLA
A17: 9 | B17: =Theory!B25 -> 1DS21AI019 | C17: =Theory!C25 -> HARIKRISHNA M
A18: 10 | B18: =Theory!B26 -> 1DS21AI020 | C18: =Theory!C26 -> HARSHITHA B
A19: 11 | B19: =Theory!B27 -> 1DS21AI021 | C19: =Theory!C27 -> HARSHITHA S
A20: 12 | B20: =Theory!B28 -> 1DS21AI023 | C20: =Theory!C28 -> HITHA N
... A75: 67 | B75: =Theory!B83 -> 0 | C75: =Theory!C83 -> 0
C82: A=No. of Students Attempted the Question | D82: =COUNTIFS(D9:D78,"<>AB",D9:D78,"<>NA",D9:D78,"<>") -> 0 | E82: =COUNTIFS(E9:E78,"<>AB",E9:E78,"<>NA",E9:E78,"<>") -> 0 | F82: =COUNTIFS(F9:F78,"<>AB",F9:F78,"<>NA",F9:F78,"<>") -> 0 | G82: =COUNTIFS(G9:G78,"<>AB",G9:G78,"<>NA",G9:G78,"<>") -> 0 | H82: =COUNTIFS(H9:H78,"<>AB",H9:H78,"<>NA",H9:H78,"<>") -> 0 | I82: =COUNTIFS(I9:I78,"<>AB",I9:I78,"<>NA",I9:I78,"<>") -> 0 | J82: =COUNTIFS(J9:J78,"<>AB",J9:J78,"<>NA",J9:J78,"<>") -> 0 | K82: =COUNTIFS(K12:K81,"<>AB",K12:K81,"<>NA",K12:K81,"<>") -> 0
C83: B=Sum of Marks > 60% | D83: =SUMIF(D9:D78,">="&D7,D9:D78) -> 0 | E83: =SUMIF(E9:E78,">="&E7,E9:E78) -> 0 | F83: =SUMIF(F9:F78,">="&F7,F9:F78) -> 0 | G83: =SUMIF(G9:G78,">="&G7,G9:G78) -> 0 | H83: =SUMIF(H9:H78,">="&H7,H9:H78) -> 0 | I83: =SUMIF(I9:I78,">="&I7,I9:I78) -> 0 | J83: =SUMIF(J9:J78,">="&J7,J9:J78) -> 0 | K83: =SUMIF(K12:K81,">="&K10,K12:K81) -> 0
C84: CO Attainment = B/A | D84: =IF(D82<>0,((D83/D82)/D6)*100,0) -> 0 | E84: =IF(E82<>0,((E83/E82)/E6)*100,0) -> 0 | F84: =IF(F82<>0,((F83/F82)/F6)*100,0) -> 0 | G84: =IF(G82<>0,((G83/G82)/G6)*100,0) -> 0 | H84: =IF(H82<>0,((H83/H82)/H6)*100,0) -> 0 | I84: =IF(I82<>0,((I83/I82)/I6)*100,0) -> 0 | J84: =IF(J82<>0,((J83/J82)/J6)*100,0) -> 0 | K84: =VALUE(IF(K82<>0,(COUNTIF(K12:K81,"=S")*10+COUNTIF(K12:K81,"=A")*9+COUNTIF(K12:K81,"=B")*8+COUNTIF(K12:K81,"=C")*7+COUNTIF(K12:K81,"=D")*5+COUNTIF(K12:K81,"=E")*4)/(10*COUNTIF(K12:K81,"<>"&""))*100,0)) -> 0
C88: CO Attainment of LAB Total Percentage (Average) | D88: CO1 | E88: CO2 | F88: CO3 | G88: CO4 | H88: CO5 | I88: CO6
C89: CO Attainment | D89: {=IFERROR( AVERAGE(_xlfn._xlws.FILTER(D84:I84,_xlfn.BYCOL(D5:I5, _xlfn.LAMBDA(_xlpm.x, ISNUMBER(MATCH(1, --_xlfn.TEXTSPLIT(_xlpm.x, ","), 0)))))),"")} | E89: {=IFERROR( AVERAGE(_xlfn._xlws.FILTER(D84:I84,_xlfn.BYCOL(D5:I5, _xlfn.LAMBDA(_xlpm.x, ISNUMBER(MATCH(2, --_xlfn.TEXTSPLIT(_xlpm.x, ","), 0)))))),"")} | F89: {=IFERROR( AVERAGE(_xlfn._xlws.FILTER(D84:I84,_xlfn.BYCOL(D5:I5, _xlfn.LAMBDA(_xlpm.x, ISNUMBER(MATCH(3, --_xlfn.TEXTSPLIT(_xlpm.x, ","), 0)))))),"")} | G89: {=IFERROR( AVERAGE(_xlfn._xlws.FILTER(D84:I84,_xlfn.BYCOL(D5:I5, _xlfn.LAMBDA(_xlpm.x, ISNUMBER(MATCH(4, --_xlfn.TEXTSPLIT(_xlpm.x, ","), 0)))))),"")} | H89: {=IFERROR( AVERAGE(_xlfn._xlws.FILTER(D84:I84,_xlfn.BYCOL(D5:I5, _xlfn.LAMBDA(_xlpm.x, ISNUMBER(MATCH(5, --_xlfn.TEXTSPLIT(_xlpm.x, ","), 0)))))),"")} | I89: {=IFERROR( AVERAGE(_xlfn._xlws.FILTER(D84:I84,_xlfn.BYCOL(D5:I5, _xlfn.LAMBDA(_xlpm.x, ISNUMBER(MATCH(6, --_xlfn.TEXTSPLIT(_xlpm.x, ","), 0)))))),"")}
C96: PO Attainment (LAB) | D96: PO1 | E96: PO2 | F96: PO3 | G96: PO4 | H96: PO5 | I96: PO6 | J96: PO7 | K96: PO8 | L96: PO9 | M96: PO10 | N96: PO11 | O96: PO12
C97: Case 1 | D97: =IF(COUNTIFS($D$4:$I$4,"=*,1,*",$D84:$I84,"<>0")=0,0,SUMIF($D$4:$I$4,"=*,1,*",$D84:$I84)/COUNTIFS($D$4:$I$4,"=*,1,*",$D84:$I84,"<>0")) -> 0 | E97: =IF(COUNTIFS($D$4:$I$4,"=*,2,*",$D84:$I84,"<>0")=0,0,SUMIF($D$4:$I$4,"=*,2,*",$D84:$I84)/COUNTIFS($D$4:$I$4,"=*,2,*",$D84:$I84,"<>0")) -> 0 | F97: =IF(COUNTIFS($D$4:$I$4,"=*,3,*",$D84:$I84,"<>0")=0,0,SUMIF($D$4:$I$4,"=*,3,*",$D84:$I84)/COUNTIFS($D$4:$I$4,"=*,3,*",$D84:$I84,"<>0")) -> 0 | G97: =IF(COUNTIFS($D$4:$I$4,"=*,4,*",$D84:$I84,"<>0")=0,0,SUMIF($D$4:$I$4,"=*,4,*",$D84:$I84)/COUNTIFS($D$4:$I$4,"=*,4,*",$D84:$I84,"<>0")) -> 0 | H97: =IF(COUNTIFS($D$4:$I$4,"=*,5,*",$D84:$I84,"<>0")=0,0,SUMIF($D$4:$I$4,"=*,5,*",$D84:$I84)/COUNTIFS($D$4:$I$4,"=*,5,*",$D84:$I84,"<>0")) -> 0 | I97: =IF(COUNTIFS($D$4:$I$4,"=*,6,*",$D84:$I84,"<>0")=0,0,SUMIF($D$4:$I$4,"=*,6,*",$D84:$I84)/COUNTIFS($D$4:$I$4,"=*,6,*",$D84:$I84,"<>0")) -> 0 | J97: =IF(COUNTIFS($D$4:$I$4,"=*,7,*",$D84:$I84,"<>0")=0,0,SUMIF($D$4:$I$4,"=*,7,*",$D84:$I84)/COUNTIFS($D$4:$I$4,"=*,7,*",$D84:$I84,"<>0")) -> 0 | K97: =IF(COUNTIFS($D$4:$I$4,"=*,8,*",$D84:$I84,"<>0")=0,0,SUMIF($D$4:$I$4,"=*,8,*",$D84:$I84)/COUNTIFS($D$4:$I$4,"=*,8,*",$D84:$I84,"<>0")) -> 0 | L97: =IF(COUNTIFS($D$4:$I$4,"=*,9,*",$D84:$I84,"<>0")=0,0,SUMIF($D$4:$I$4,"=*,9,*",$D84:$I84)/COUNTIFS($D$4:$I$4,"=*,9,*",$D84:$I84,"<>0")) -> 0 | M97: =IF(COUNTIFS($D$4:$I$4,"=*,10,*",$D84:$I84,"<>0")=0,0,SUMIF($D$4:$I$4,"=*,10,*",$D84:$I84)/COUNTIFS($D$4:$I$4,"=*,10,*",$D84:$I84,"<>0")) -> 0 | N97: =IF(COUNTIFS($D$4:$I$4,"=*,11,*",$D84:$I84,"<>0")=0,0,SUMIF($D$4:$I$4,"=*,11,*",$D84:$I84)/COUNTIFS($D$4:$I$4,"=*,11,*",$D84:$I84,"<>0")) -> 0 | O97: =IF(COUNTIFS($D$4:$I$4,"=*,12,*",$D84:$I84,"<>0")=0,0,SUMIF($D$4:$I$4,"=*,12,*",$D84:$I84)/COUNTIFS($D$4:$I$4,"=*,12,*",$D84:$I84,"<>0")) -> 0

Sheet CIA MARKS
A2: =Theory!A7 -> STAND ALONE THEORY | C2: =Theory!D7 -> YES
A3: =Theory!A8 -> STAND ALONE LAB | C3: =Theory!D8 -> NO
A4: =Theory!A9 -> IPCC | C4: =Theory!D9 -> NO
A5: =Theory!A4 -> Academic Year : 2023 -24
A6: =Theory!D4 -> Scheme :2021-25
A7: =Theory!A6 -> COURSE TITLE :IoT & 5G | D7: =Theory!A10 -> 0 | S7: CO # | V7: CO1 | W7: CO2 | X7: CO3 | Y7: CO4 | Z7: CO5 | AA7: CO6
A8: =Theory!A5 -> COURSE CODE : 21AI643 | S8: CO Targets: | V8: 60 | W8: 60 | X8: 60 | Y8: 60 | Z8: 60 | AA8: 60 | AO8: IA1-TOTAL | CA8: IA2-TOTAL | DM8: IA3-TOTAL
A9: =Theory!Q4 -> Semester : 6th | D9: IAT-1 | AP9: IAT-2 | CB9: IAT-3 | DN9: CIA-1 (50) | DO9: CIA-2 (50) | DP9: CIA-3 (50) | DQ9: CIA-1 (30) | DR9: CIA-2 (30) | DS9: CIA-3 (30) | DT9: AVG CIA (30) | DU9: AAT (10) | DV9: QUIZ (10) | DW9: AAT+QUIZ (10+10) | DX9: THEORY CIA (50) | DY9: THEORY CIA (30) | DZ9: Lab-CIE (30) | ED9: LAB IA (20) | EH9: LAB (50) | EI9: LAB CIA (20) | EJ9: CIA | EK9: SEE | EM9: ATTENDANCE FOR CSV FILE
A10: Question maps to which course outcome? | D10: =Theory!D12 -> 0,1 | E10: =Theory!E12 -> 0 | F10: =Theory!F12 -> 0 | G10: =Theory!G12 -> 0 | I10: =Theory!H12 -> 0,1 | J10: =Theory!I12 -> 0 | K10: =Theory!J12 -> 0 | L10: =Theory!K12 -> 0 | N10: =Theory!L12 -> 0,1 | O10: =Theory!M12 -> 0 | P10: =Theory!N12 -> 0 | Q10: =Theory!O12 -> 0 | R10: =Theory!P12 -> 0,1 | S10: =Theory!Q12 -> 0 | T10: =Theory!R12 -> 0 | U10: =Theory!S12 -> 0 | W10: =Theory!T12 -> 0,1 | X10: =Theory!U12 -> 0 | Y10: =Theory!V12 -> 0 | Z10: =Theory!W12 -> 0 | AA10: =Theory!X12 -> 0,1 | AB10: =Theory!Y12 -> 0 | AC10: =Theory!Z12 -> 0 | AD10: =Theory!AA12 -> 0 | AF10: =Theory!AB12 -> 0,1 | AG10: =Theory!AC12 -> 0 | AH10: =Theory!AD12 -> 0 | AI10: =Theory!AE12 -> 0 | AJ10: =Theory!AF12 -> 0,1 | AK10: =Theory!AG12 -> 0 | AL10: =Theory!AH12 -> 0 | AM10: =Theory!AI12 -> 0 | AP10: =Theory!AJ12 -> 0,4 | AQ10: =Theory!AK12 -> 0 | AR10: =Theory!AL12 -> 0 | AS10: =Theory!AM12 -> 0 | AU10: =Theory!AN12 -> 0,4 | AV10: =Theory!AO12 -> 0,4 | AW10: =Theory!AP12 -> 0 | AX10: =Theory!AQ12 -> 0 | AZ10: =Theory!AR12 -> 0,2 | BA10: =Theory!AS12 -> 0 | BB10: =Theory!AT12 -> 0 | BC10: =Theory!AU12 -> 0 | BD10: =Theory!AV12 -> 0,2 | BE10: =Theory!AW12 -> 0 | BF10: =Theory!AX12 -> 0 | BG10: =Theory!AY12 -> 0 | BI10: =Theory!AZ12 -> 0,4 | BJ10: =Theory!BA12 -> 0 | BK10: =Theory!BB12 -> 0 | BL10: =Theory!BC12 -> 0 | BM10: =Theory!BD12 -> 0,4 | BN10: =Theory!BE12 -> 0 | BO10: =Theory!BF12 -> 0 | BP10: =Theory!BG12 -> 0 | BR10: =Theory!BH12 -> 0,4 | BS10: =Theory!BI12 -> 0 | BT10: =Theory!BJ12 -> 0 | BU10: =Theory!BK12 -> 0 | BV10: =Theory!BL12 -> 0,4 | BW10: =Theory!BM12 -> 0 | BX10: =Theory!BN12 -> 0 | BY10: =Theory!BO12 -> 0 | CB10: =Theory!BP12 -> 0,3 | CC10: =Theory!BQ12 -> 0 | CD10: =Theory!BR12 -> 0 | CE10: =Theory!BS12 -> 0 | CG10: =Theory!BT12 -> 0,4 | CH10: =Theory!BU12 -> 0 | CI10: =Theory!BV12 -> 0 | CJ10: =Theory!BW12 -> 0 | CL10: =Theory!BX12 -> 0,3 | CM10: =Theory!BY12 -> 0 | CN10: =Theory!BZ12 -> 0 | CO10: =Theory!CA12 -> 0 | CP10: =Theory!CB12 -> 0,3 | CQ10: =Theory!CC12 -> 0 | CR10: =Theory!CD12 -> 0 | CS10: =Theory!CE12 -> 0 | CU10: =Theory!CF12 -> 0,3 | CV10: =Theory!CG12 -> 0 | CW10: =Theory!CH12 -> 0 | CX10: =Theory!CI12 -> 0 | CY10: =Theory!CJ12 -> 0,3 | CZ10: =Theory!CK12 -> 0 | DA10: =Theory!CL12 -> 0 | DB10: =Theory!CM12 -> 0 | DD10: =Theory!CN12 -> 0,4 | DE10: =Theory!CO12 -> 0 | DF10: =Theory!CP12 -> 0 | DG10: =Theory!CQ12 -> 0 | DH10: =Theory!CR12 -> 0,4 | DI10: =Theory!CS12 -> 0 | DJ10: =Theory!CT12 -> 0 | DK10: =Theory!CU12 -> 0 | DY10: 0,1,2,3,4,5 | EI10: 0,5,6 | EJ10: 0,1,2,3,4,5,6 | EK10: 0,1,2,3,4 | EM10: ATTND (11/12) | EN10: ATTND (11/24) | EO10: ATTND (34/40) | EP10: ATTND (34/40) | EQ10: ATTND (11/12) | ER10: ATT-THEORY (34/40) | ES10: ATT-LAB (11/12)
D11: =Theory!D16 -> Q1A | E11: =Theory!E16 -> Q1B | F11: =Theory!F16 -> Q1C | G11: =Theory!G16 -> Q1D | I11: =Theory!H16 -> Q2A | J11: =Theory!I16 -> Q2B | K11: =Theory!J16 -> Q2C | L11: =Theory!K16 -> Q2D | N11: =Theory!L16 -> Q3A | O11: =Theory!M16 -> Q3B | P11: =Theory!N16 -> Q3C | Q11: =Theory!O16 -> Q3D | R11: =Theory!P16 -> Q4A | S11: =Theory!Q16 -> Q4B | T11: =Theory!R16 -> Q4C | U11: =Theory!S16 -> Q4D | W11: =Theory!T16 -> Q5A | X11: =Theory!U16 -> Q5B | Y11: =Theory!V16 -> Q5C | Z11: =Theory!W16 -> Q5D | AA11: =Theory!X16 -> Q6A | AB11: =Theory!Y16 -> Q6B | AC11: =Theory!Z16 -> Q6C | AD11: =Theory!AA16 -> Q6D | AF11: =Theory!AB16 -> Q7A | AG11: =Theory!AC16 -> Q7B | AH11: =Theory!AD16 -> Q7C | AI11: =Theory!AE16 -> Q7D | AJ11: =Theory!AF16 -> Q8A | AK11: =Theory!AG16 -> Q8B | AL11: =Theory!AH16 -> Q8C | AM11: =Theory!AI16 -> Q8D | AP11: =Theory!AJ16 -> Q1A | AQ11: =Theory!AK16 -> Q1A | AR11: =Theory!AL16 -> Q1C | AS11: =Theory!AM16 -> Q1D | AU11: =Theory!AN16 -> Q2A | AV11: =Theory!AO16 -> Q2A | AW11: =Theory!AP16 -> Q2C | AX11: =Theory!AQ16 -> Q2D | AZ11: =Theory!AR16 -> Q3A | BA11: =Theory!AS16 -> Q3B | BB11: =Theory!AT16 -> Q3C | BC11: =Theory!AU16 -> Q3D | BD11: =Theory!AV16 -> Q4A | BE11: =Theory!AW16 -> Q4B | BF11: =Theory!AX16 -> Q4C | BG11: =Theory!AY16 -> Q4D | BI11: =Theory!AZ16 -> Q5A | BJ11: =Theory!BA16 -> Q5B | BK11: =Theory!BB16 -> Q5C | BL11: =Theory!BC16 -> Q5D | BM11: =Theory!BD16 -> Q6A | BN11: =Theory!BE16 -> Q6B | BO11: =Theory!BF16 -> Q6C | BP11: =Theory!BG16 -> Q6D | BR11: =Theory!BH16 -> Q7A | BS11: =Theory!BI16 -> Q7B | BT11: =Theory!BJ16 -> Q7C | BU11: =Theory!BK16 -> Q7D | BV11: =Theory!BL16 -> Q8A | BW11: =Theory!BM16 -> Q8B | BX11: =Theory!BN16 -> Q8C | BY11: =Theory!BO16 -> Q8D | CB11: =Theory!BP16 -> Q1A | CC11: =Theory!BQ16 -> Q1B | CD11: =Theory!BR16 -> Q1C | CE11: =Theory!BS16 -> Q1D | CG11: =Theory!BT16 -> Q2A | CH11: =Theory!BU16 -> Q2B | CI11: =Theory!BV16 -> Q2C | CJ11: =Theory!BW16 -> Q2D | CL11: =Theory!BX16 -> Q3A | CM11: =Theory!BY16 -> Q3B | CN11: =Theory!BZ16 -> Q3C | CO11: =Theory!CA16 -> Q3D | CP11: =Theory!CB16 -> Q4A | CQ11: =Theory!CC16 -> Q4B | CR11: =Theory!CD16 -> Q4C | CS11: =Theory!CE16 -> Q4D | CU11: =Theory!CF16 -> Q5A | CV11: =Theory!CG16 -> Q5B | CW11: =Theory!CH16 -> Q5C | CX11: =Theory!CI16 -> Q5D | CY11: =Theory!CJ16 -> Q6A | CZ11: =Theory!CK16 -> Q6B | DA11: =Theory!CL16 -> Q6C | DB11: =Theory!CM16 -> Q6D | DD11: =Theory!CN16 -> Q7A | DE11: =Theory!CO16 -> Q7B | DF11: =Theory!CP16 -> Q7C | DG11: =Theory!CQ16 -> Q7D | DH11: =Theory!CR16 -> Q8A | DI11: =Theory!CS16 -> Q8B | DJ11: =Theory!CT16 -> Q8C | DK11: =Theory!CU16 -> Q8D | DT11: CIA | DU11: AAT | DV11: QUIZ | DW11: AAT+QUIZ | DX11: THEORY CIA (50) | DY11: THEORY CIA (30) | EC11: Lab-CIE (30) | EG11: LAB IA (20) | EH11: LAB | EI11: LAB CIA (20) | EJ11: CIA (50) | EK11: SEE (50) | EM11: CREDIT-1 | EN11: CREDIT-2 | EO11: CREDIT-3 | EP11: CREDIT-4 | EQ11: LAB CREDIT-1 | ER11: CREDIT-4
A12: Sl NO | B12: Name | C12: USN | DT12: TEST (12/30) | DW12: AAT (8/20) | DX12: STAND ALONE THEORY | EC12: LAB-CLASS WORK (12/30) | EG12: LAB-TEST (8/20) | EH12: STAND ALONE LAB | EJ12: IPCC | EK12: SEE | EM12: STAND ALONE THEORY ATTENDANCE | EN12: STAND ALONE THEORY ATTENDANCE | EO12: STAND ALONE THEORY ATTENDANCE | EP12: STAND ALONE THEORY ATTENDANCE | EQ12: STAND ALONE LAB ATTENDANCE | ER12: IPCC THEORY ATTENDANCE | ES12: IPCC LAB ATTENDANCE | ET12: IPCC TOTAL ATTENDANCE
C13: MAX MARKS | D13: =Theory!D14 -> 10 | E13: =Theory!E14 -> 0 | F13: =Theory!F14 -> 0 | G13: =Theory!G14 -> 0 | H13: =SUM(D13:G13) -> 10 | I13: =Theory!H14 -> 10 | J13: =Theory!I14 -> 0 | K13: =Theory!J14 -> 0 | L13: =Theory!K14 -> 0 | M13: =SUM(I13:L13) -> 10 | N13: =Theory!L14 -> 10 | O13: =Theory!M14 -> 0 | P13: =Theory!N14 -> 0 | Q13: =Theory!O14 -> 0 | R13: =Theory!P14 -> 10 | S13: =Theory!Q14 -> 0 | T13: =Theory!R14 -> 0 | U13: =Theory!S14 -> 0 | V13: =MAX(SUM(N13:Q13),SUM(R13:U13)) -> 10 | W13: =Theory!T14 -> 10 | X13: =Theory!U14 -> 0 | Y13: =Theory!V14 -> 0 | Z13: =Theory!W14 -> 0 | AA13: =Theory!X14 -> 10 | AB13: =Theory!Y14 -> 0 | AC13: =Theory!Z14 -> 0 | AD13: =Theory!AA14 -> 0 | AE13: =MAX(SUM(W13:Z13),SUM(AA13:AD13)) -> 10 | AF13: =Theory!AB14 -> 10 | AG13: =Theory!AC14 -> 0 | AH13: =Theory!AD14 -> 0 | AI13: =Theory!AE14 -> 0 | AJ13: =Theory!AF14 -> 10 | AK13: =Theory!AG14 -> 0 | AL13: =Theory!AH14 -> 0 | AM13: =Theory!AI14 -> 0 | AN13: =MAX(SUM(AF13:AI13),SUM(AJ13:AM13)) -> 10 | AO13: =SUM(H13,M13,V13,AE13,AN13) -> 50 | AP13: =Theory!AJ14 -> 10 | AQ13: =Theory!AK14 -> 0 | AR13: =Theory!AL14 -> 0 | AS13: =Theory!AM14 -> 0 | AT13: =SUM(AP13:AS13) -> 10 | AU13: =Theory!AN14 -> 5 | AV13: =Theory!AO14 -> 5 | AW13: =Theory!AP14 -> 0 | AX13: =Theory!AQ14 -> 0 | AY13: =SUM(AU13:AX13) -> 10 | AZ13: =Theory!AR14 -> 10 | BA13: =Theory!AS14 -> 0 | BB13: =Theory!AT14 -> 0 | BC13: =Theory!AU14 -> 0 | BD13: =Theory!AV14 -> 10 | BE13: =Theory!AW14 -> 0 | BF13: =Theory!AX14 -> 0 | BG13: =Theory!AY14 -> 0 | BH13: =MAX(SUM(AZ13:BC13),SUM(BD13:BG13)) -> 10 | BI13: =Theory!AZ14 -> 10 | BJ13: =Theory!BA14 -> 0 | BK13: =Theory!BB14 -> 0 | BL13: =Theory!BC14 -> 0 | BM13: =Theory!BD14 -> 10 | BN13: =Theory!BE14 -> 0 | BO13: =Theory!BF14 -> 0 | BP13: =Theory!BG14 -> 0 | BQ13: =MAX(SUM(BI13:BL13),SUM(BM13:BP13)) -> 10 | BR13: =Theory!BH14 -> 10 | BS13: =Theory!BI14 -> 0 | BT13: =Theory!BJ14 -> 0 | BU13: =Theory!BK14 -> 0 | BV13: =Theory!BL14 -> 10 | BW13: =Theory!BM14 -> 0 | BX13: =Theory!BN14 -> 0 | BY13: =Theory!BO14 -> 0 | BZ13: =MAX(SUM(BR13:BU13),SUM(BV13:BY13)) -> 10 | CA13: =SUM(AT13,AY13,BH13,BQ13,BZ13) -> 50 | CB13: =Theory!BP14 -> 10 | CC13: =Theory!BQ14 -> 0 | CD13: =Theory!BR14 -> 0 | CE13: =Theory!BS14 -> 0 | CF13: =SUM(CB13:CE13) -> 10 | CG13: =Theory!BT14 -> 10 | CH13: =Theory!BU14 -> 0 | CI13: =Theory!BV14 -> 0 | CJ13: =Theory!BW14 -> 0 | CK13: =SUM(CG13:CJ13) -> 10 | CL13: =Theory!BX14 -> 10 | CM13: =Theory!BY14 -> 0 | CN13: =Theory!BZ14 -> 0 | CO13: =Theory!CA14 -> 0 | CP13: =Theory!CB14 -> 10 | CQ13: =Theory!CC14 -> 0 | CR13: =Theory!CD14 -> 0 | CS13: =Theory!CE14 -> 0 | CT13: =MAX(SUM(CL13:CO13),SUM(CP13:CS13)) -> 10 | CU13: =Theory!CF14 -> 10 | CV13: =Theory!CG14 -> 0 | CW13: =Theory!CH14 -> 0 | CX13: =Theory!CI14 -> 0 | CY13: =Theory!CJ14 -> 10 | CZ13: =Theory!CK14 -> 0 | DA13: =Theory!CL14 -> 0 | DB13: =Theory!CM14 -> 0 | DC13: =MAX(SUM(CU13:CX13),SUM(CY13:DB13)) -> 10 | DD13: =Theory!CN14 -> 10 | DE13: =Theory!CO14 -> 0 | DF13: =Theory!CP14 -> 0 | DG13: =Theory!CQ14 -> 0 | DH13: =Theory!CR14 -> 10 | DI13: =Theory!CS14 -> 0 | DJ13: =Theory!CT14 -> 0 | DK13: =Theory!CU14 -> 0 | DL13: =MAX(SUM(DD13:DG13),SUM(DH13:DK13)) -> 10 | DM13: =SUM(CF13,CK13,CT13,DC13,DL13) -> 50 | DN13: =AO13 -> 50 | DO13: =CA13 -> 50 | DP13: =DM13 -> 50 | DQ13: =ROUND(30*DN13/50,0) -> 30 | DR13: =ROUND(30*DO13/50,0) -> 30 | DS13: =ROUND(30*DP13/50,0) -> 30 | DT13: =ROUND(AVERAGE(DQ13:DS13),0) -> 30 | DU13: =Theory!CV14 -> 10 | DV13: =Theory!CW14 -> 10 | DW13: =SUM(DU13:DV13) -> 20 | DX13: =SUM(DT13:DV13) -> 50 | DY13: =ROUND((30*DX13/50),0) -> 30 | DZ13: =Lab!D6 -> 0 | EA13: =Lab!E6 -> 0 | EB13: =Lab!F6 -> 0 | EC13: =SUM(DZ13:EB13) -> 0 | ED13: =Lab!G6 -> 0 | EE13: =Lab!H6 -> 0 | EF13: =Lab!I6 -> 0 | EG13: =SUM(ED13:EF13) -> 0 | EH13: =SUM(EC13,EG13) -> 0 | EI13: =ROUND((20*EH13/50),0) -> 0 | EJ13: =SUM(DY13,EI13) -> 30 | EK13: =Theory!DC14 -> 50 | EM13: 12 | EN13: 24 | EO13: 40 | EP13: 52 | EQ13: 12 | ER13: 40 | ES13: 12 | ET13: =SUM(ER13:ES13) -> 52
A14: 1 | B14: =Theory!C17 -> ADITHYA N AWATI | C14: =Theory!B17 -> 1DS21AI001 | D14: =VLOOKUP(C14,Theory!B17:D83,3,FALSE) -> 9 | E14: =VLOOKUP(C14,Theory!B17:E83,4,FALSE) -> 0 | F14: =VLOOKUP(C14,Theory!B17:F83,5,FALSE) -> 0 | G14: =VLOOKUP(C14,Theory!B17:G83,6,FALSE) -> 0 | H14: =SUM(D14:G14) -> 9 | I14: =VLOOKUP(C14,Theory!B17:H83,7,FALSE) -> 8 | J14: =VLOOKUP(C14,Theory!B17:I83,8,FALSE) -> 0 | K14: =VLOOKUP(C14,Theory!B17:J83,9,FALSE) -> 0 | L14: =VLOOKUP(C14,Theory!B17:K83,10,FALSE) -> 0 | M14: =SUM(I14:L14) -> 8 | N14: =VLOOKUP(C14,Theory!B17:L83,11,FALSE) -> 8 | O14: =VLOOKUP(C14,Theory!B17:M83,12,FALSE) -> 0 | P14: =VLOOKUP(C14,Theory!B17:N83,13,FALSE) -> 0 | Q14: =VLOOKUP(C14,Theory!B17:O83,14,FALSE) -> 0 | R14: =VLOOKUP(C14,Theory!B17:P83,15,FALSE) -> 0 | S14: =VLOOKUP(C14,Theory!B17:Q83,16,FALSE) -> 0 | T14: =VLOOKUP(C14,Theory!B17:R83,17,FALSE) -> 0 | U14: =VLOOKUP(C14,Theory!B17:S83,18,FALSE) -> 0 | V14: =MAX(SUM(N14:Q14),SUM(R14:U14)) -> 8 | W14: =VLOOKUP(C14,Theory!B17:T83,19,FALSE) -> 8 | X14: =VLOOKUP(C14,Theory!B17:U83,20,FALSE) -> 0 | Y14: =VLOOKUP(C14,Theory!B17:V83,21,FALSE) -> 0 | Z14: =VLOOKUP(C14,Theory!B17:W83,22,FALSE) -> 0 | AA14: =VLOOKUP(C14,Theory!B17:X83,23,FALSE) -> 0 | AB14: =VLOOKUP(C14,Theory!B17:Y83,24,FALSE) -> 0 | AC14: =VLOOKUP(C14,Theory!B17:Z83,25,FALSE) -> 0 | AD14: =VLOOKUP(C14,Theory!B17:AA83,26,FALSE) -> 0 | AE14: =MAX(SUM(W14:Z14),SUM(AA14:AD14)) -> 8 | AF14: =VLOOKUP(C14,Theory!B17:AB83,27,FALSE) -> 9 | AG14: =VLOOKUP(C14,Theory!B17:AC83,28,FALSE) -> 0 | AH14: =VLOOKUP(C14,Theory!B17:AD83,29,FALSE) -> 0 | AI14: =VLOOKUP(C14,Theory!B17:AE83,30,FALSE) -> 0 | AJ14: =VLOOKUP(C14,Theory!B17:AF83,31,FALSE) -> 0 | AK14: =VLOOKUP(C14,Theory!B17:AG83,32,FALSE) -> 0 | AL14: =VLOOKUP(C14,Theory!B17:AH83,33,FALSE) -> 0 | AM14: =VLOOKUP(C14,Theory!B17:AI83,34,FALSE) -> 0 | AN14: =MAX(SUM(AF14:AI14),SUM(AJ14:AM14)) -> 9 | AO14: =SUM(H14,M14,V14,AE14,AN14) -> 42 | AP14: =VLOOKUP(C14,Theory!B17:AJ83,35,FALSE) -> 9 | AQ14: =VLOOKUP(C14,Theory!B17:AK83,36,FALSE) -> 0 | AR14: =VLOOKUP(C14,Theory!B17:AL83,37,FALSE) -> 0 | AS14: =VLOOKUP(C14,Theory!B17:AM83,38,FALSE) -> 0 | AT14: =SUM(AP14:AS14) -> 9 | AU14: =VLOOKUP(C14,Theory!B17:AN83,39,FALSE) -> 9 | AV14: =VLOOKUP(C14,Theory!B17:AO83,40,FALSE) -> 0 | AW14: =VLOOKUP(C14,Theory!B17:AP83,41,FALSE) -> 0 | AX14: =VLOOKUP(C14,Theory!B17:AQ83,42,FALSE) -> 0 | AY14: =SUM(AU14:AX14) -> 9 | AZ14: =VLOOKUP(C14,Theory!B17:AR83,43,FALSE) -> 9 | BA14: =VLOOKUP(C14,Theory!B17:AS83,44,FALSE) -> 0 | BB14: =VLOOKUP(C14,Theory!B17:AT83,45,FALSE) -> 0 | BC14: =VLOOKUP(C14,Theory!B17:AU83,46,FALSE) -> 0 | BD14: =VLOOKUP(C14,Theory!B17:AV83,47,FALSE) -> 0 | BE14: =VLOOKUP(C14,Theory!B17:AW83,48,FALSE) -> 0 | BF14: =VLOOKUP(C14,Theory!B17:AX83,49,FALSE) -> 0 | BG14: =VLOOKUP(C14,Theory!B17:AY83,50,FALSE) -> 0 | BH14: =MAX(SUM(AZ14:BC14),SUM(BD14:BG14)) -> 9 | BI14: =VLOOKUP(C14,Theory!B17:AZ83,51,FALSE) -> 8 | BJ14: =VLOOKUP(C14,Theory!B17:BA83,52,FALSE) -> 0 | BK14: =VLOOKUP(C14,Theory!B17:BB83,53,FALSE) -> 0 | BL14: =VLOOKUP(C14,Theory!B17:BC83,54,FALSE) -> 0 | BM14: =VLOOKUP(C14,Theory!B17:BD83,55,FALSE) -> 0 | BN14: =VLOOKUP(C14,Theory!B17:BE83,56,FALSE) -> 0 | BO14: =VLOOKUP(C14,Theory!B17:BF83,57,FALSE) -> 0 | BP14: =VLOOKUP(C14,Theory!B17:BG83,58,FALSE) -> 0 | BQ14: =MAX(SUM(BI14:BL14),SUM(BM14:BP14)) -> 8 | BR14: =VLOOKUP(C14,Theory!B17:BH83,59,FALSE) -> 10 | BS14: =VLOOKUP(C14,Theory!B17:BI83,60,FALSE) -> 0 | BT14: =VLOOKUP(C14,Theory!B17:BJ83,61,FALSE) -> 0 | BU14: =VLOOKUP(C14,Theory!B17:BK83,62,FALSE) -> 0 | BV14: =VLOOKUP(C14,Theory!B17:BL83,63,FALSE) -> 0 | BW14: =VLOOKUP(C14,Theory!B17:BM83,64,FALSE) -> 0 | BX14: =VLOOKUP(C14,Theory!B17:BN83,65,FALSE) -> 0 | BY14: =VLOOKUP(C14,Theory!B17:BO83,66,FALSE) -> 0 | BZ14: =MAX(SUM(BR14:BU14),SUM(BV14:BY14)) -> 10 | CA14: =SUM(AT14,AY14,BH14,BQ14,BZ14) -> 45 | CB14: =VLOOKUP(C14,Theory!B17:BP83,67,FALSE) -> 7 | CC14: =VLOOKUP(C14,Theory!B17:BQ83,68,FALSE) -> 0 | CD14: =VLOOKUP(C14,Theory!B17:BR83,69,FALSE) -> 0 | CE14: =VLOOKUP(C14,Theory!B17:BS83,70,FALSE) -> 0 | CF14: =SUM(CB14:CE14) -> 7 | CG14: =VLOOKUP(C14,Theory!B17:BT83,71,FALSE) -> 9 | CH14: =VLOOKUP(C14,Theory!B17:BU83,72,FALSE) -> 0 | CI14: =VLOOKUP(C14,Theory!B17:BV83,73,FALSE) -> 0 | CJ14: =VLOOKUP(C14,Theory!B17:BW83,74,FALSE) -> 0 | CK14: =SUM(CG14:CJ14) -> 9 | CL14: =VLOOKUP(C14,Theory!B17:BX83,75,FALSE) -> 10 | CM14: =VLOOKUP(C14,Theory!B17:BY83,76,FALSE) -> 0 | CN14: =VLOOKUP(C14,Theory!B17:BZ83,77,FALSE) -> 0 | CO14: =VLOOKUP(C14,Theory!B17:CA83,78,FALSE) -> 0 | CP14: =VLOOKUP(C14,Theory!B17:CB83,79,FALSE) -> 0 | CQ14: =VLOOKUP(C14,Theory!B17:CC83,80,FALSE) -> 0 | CR14: =VLOOKUP(C14,Theory!B17:CD83,81,FALSE) -> 0 | CS14: =VLOOKUP(C14,Theory!B17:CE83,82,FALSE) -> 0 | CT14: =MAX(SUM(CL14:CO14),SUM(CP14:CS14)) -> 10 | CU14: =VLOOKUP(C14,Theory!B17:CF83,83,FALSE) -> 9 | CV14: =VLOOKUP(C14,Theory!B17:CG83,84,FALSE) -> 0 | CW14: =VLOOKUP(C14,Theory!B17:CH83,85,FALSE) -> 0 | CX14: =VLOOKUP(C14,Theory!B17:CI83,86,FALSE) -> 0 | CY14: =VLOOKUP(C14,Theory!B17:CJ83,87,FALSE) -> 0 | CZ14: =VLOOKUP(C14,Theory!B17:CK83,88,FALSE) -> 0 | DA14: =VLOOKUP(C14,Theory!B17:CL83,89,FALSE) -> 0 | DB14: =VLOOKUP(C14,Theory!B17:CM83,90,FALSE) -> 0 | DC14: =MAX(SUM(CU14:CX14),SUM(CY14:DB14)) -> 9 | DD14: =VLOOKUP(C14,Theory!B17:CN83,91,FALSE) -> 8 | DE14: =VLOOKUP(C14,Theory!B17:CO83,92,FALSE) -> 0 | DF14: =VLOOKUP(C14,Theory!B17:CP83,93,FALSE) -> 0 | DG14: =VLOOKUP(C14,Theory!B17:CQ83,94,FALSE) -> 0 | DH14: =VLOOKUP(C14,Theory!B17:CR83,95,FALSE) -> 0 | DI14: =VLOOKUP(C14,Theory!B17:CS83,96,FALSE) -> 0 | DJ14: =VLOOKUP(C14,Theory!B17:CT83,97,FALSE) -> 0 | DK14: =VLOOKUP(C14,Theory!B17:CU83,98,FALSE) -> 0 | DL14: =MAX(SUM(DD14:DG14),SUM(DH14:DK14)) -> 8 | DM14: =SUM(CF14,CK14,CT14,DC14,DL14) -> 43 | DN14: =AO14 -> 42 | DO14: =CA14 -> 45 | DP14: =DM14 -> 43 | DQ14: =ROUND(30*DN14/50,0) -> 25 | DR14: =ROUND(30*DO14/50,0) -> 27 | DS14: =ROUND(30*DP14/50,0) -> 26 | DT14: =ROUND(AVERAGE(DQ14:DS14),0) -> 26 | DU14: =VLOOKUP(C14,Theory!B17:CV83,99,FALSE) -> 10 | DV14: =VLOOKUP(C14,Theory!B17:CW83,100,FALSE) -> 5 | DW14: =SUM(DU14:DV14) -> 15 | DX14: =SUM(DT14:DV14) -> 41 | DY14: =ROUND((30*DX14/50),0) -> 25 | DZ14: =VLOOKUP(C14,Lab!B9:D78,3,FALSE) -> 0 | EA14: =VLOOKUP(C14,Lab!B9:E78,4,FALSE) -> 0 | EB14: =VLOOKUP(C14,Lab!B9:F78,5,FALSE) -> 0 | EC14: =SUM(DZ14:EB14) -> 0 | ED14: =VLOOKUP(C14,Lab!B9:G78,6,FALSE) -> 0 | EE14: =VLOOKUP(C14,Lab!B9:H78,7,FALSE) -> 0 | EF14: =VLOOKUP(C14,Lab!B9:I78,8,FALSE) -> 0 | EG14: =SUM(ED14:EF14) -> 0 | EH14: =SUM(EC14,EG14) -> 0 | EI14: =ROUND((20*EH14/50),0) -> 0 | EJ14: =SUM(DY14,EI14) -> 25 | EK14: {=IF(D$8="YES",Lab!K9:K78,Theory!DC17:DC83)} -> 42 | EM14: =VLOOKUP(C14,Theory!B17:DL83,114,FALSE) -> 0 | EN14: =VLOOKUP(C14,Theory!B17:DM83,115,FALSE) -> 0 | EO14: =VLOOKUP(C14,Theory!B17:DN83,116,FALSE) -> 0 | EP14: =VLOOKUP(C14,Theory!B17:DO83,117,FALSE) -> 0 | EQ14: =VLOOKUP(C14,Theory!B17:DP83,118,FALSE) -> 0 | ER14: =VLOOKUP(C14,Theory!B17:DQ83,119,FALSE) -> 0 | ES14: =VLOOKUP(C14,Theory!B17:DR83,120,FALSE) -> 0 | ET14: =SUM(ER14:ES14) -> 0
A15: 2 | B15: =Theory!C18 -> AMIT A | C15: =Theory!B18 -> 1DS21AI002 | D15: =VLOOKUP(C15,Theory!B18:D84,3,FALSE) -> 9 | E15: =VLOOKUP(C15,Theory!B18:E84,4,FALSE) -> 0 | F15: =VLOOKUP(C15,Theory!B18:F84,5,FALSE) -> 0 | G15: =VLOOKUP(C15,Theory!B18:G84,6,FALSE) -> 0 | H15: =SUM(D15:G15) -> 9 | I15: =VLOOKUP(C15,Theory!B18:H84,7,FALSE) -> 9 | J15: =VLOOKUP(C15,Theory!B18:I84,8,FALSE) -> 0 | K15: =VLOOKUP(C15,Theory!B18:J84,9,FALSE) -> 0 | L15: =VLOOKUP(C15,Theory!B18:K84,10,FALSE) -> 0 | M15: =SUM(I15:L15) -> 9 | N15: =VLOOKUP(C15,Theory!B18:L84,11,FALSE) -> 10 | O15: =VLOOKUP(C15,Theory!B18:M84,12,FALSE) -> 0 | P15: =VLOOKUP(C15,Theory!B18:N84,13,FALSE) -> 0 | Q15: =VLOOKUP(C15,Theory!B18:O84,14,FALSE) -> 0 | R15: =VLOOKUP(C15,Theory!B18:P84,15,FALSE) -> 0 | S15: =VLOOKUP(C15,Theory!B18:Q84,16,FALSE) -> 0 | T15: =VLOOKUP(C15,Theory!B18:R84,17,FALSE) -> 0 | U15: =VLOOKUP(C15,Theory!B18:S84,18,FALSE) -> 0 | V15: =MAX(SUM(N15:Q15),SUM(R15:U15)) -> 10 | W15: =VLOOKUP(C15,Theory!B18:T84,19,FALSE) -> 10 | X15: =VLOOKUP(C15,Theory!B18:U84,20,FALSE) -> 0 | Y15: =VLOOKUP(C15,Theory!B18:V84,21,FALSE) -> 0 | Z15: =VLOOKUP(C15,Theory!B18:W84,22,FALSE) -> 0 | AA15: =VLOOKUP(C15,Theory!B18:X84,23,FALSE) -> 0 | AB15: =VLOOKUP(C15,Theory!B18:Y84,24,FALSE) -> 0 | AC15: =VLOOKUP(C15,Theory!B18:Z84,25,FALSE) -> 0 | AD15: =VLOOKUP(C15,Theory!B18:AA84,26,FALSE) -> 0 | AE15: =MAX(SUM(W15:Z15),SUM(AA15:AD15)) -> 10 | AF15: =VLOOKUP(C15,Theory!B18:AB84,27,FALSE) -> 10 | AG15: =VLOOKUP(C15,Theory!B18:AC84,28,FALSE) -> 0 | AH15: =VLOOKUP(C15,Theory!B18:AD84,29,FALSE) -> 0 | AI15: =VLOOKUP(C15,Theory!B18:AE84,30,FALSE) -> 0 | AJ15: =VLOOKUP(C15,Theory!B18:AF84,31,FALSE) -> 0 | AK15: =VLOOKUP(C15,Theory!B18:AG84,32,FALSE) -> 0 | AL15: =VLOOKUP(C15,Theory!B18:AH84,33,FALSE) -> 0 | AM15: =VLOOKUP(C15,Theory!B18:AI84,34,FALSE) -> 0 | AN15: =MAX(SUM(AF15:AI15),SUM(AJ15:AM15)) -> 10 | AO15: =SUM(H15,M15,V15,AE15,AN15) -> 48 | AP15: =VLOOKUP(C15,Theory!B18:AJ84,35,FALSE) -> 9 | AQ15: =VLOOKUP(C15,Theory!B18:AK84,36,FALSE) -> 0 | AR15: =VLOOKUP(C15,Theory!B18:AL84,37,FALSE) -> 0 | AS15: =VLOOKUP(C15,Theory!B18:AM84,38,FALSE) -> 0 | AT15: =SUM(AP15:AS15) -> 9 | AU15: =VLOOKUP(C15,Theory!B18:AN84,39,FALSE) -> 9 | AV15: =VLOOKUP(C15,Theory!B18:AO84,40,FALSE) -> 0 | AW15: =VLOOKUP(C15,Theory!B18:AP84,41,FALSE) -> 0 | AX15: =VLOOKUP(C15,Theory!B18:AQ84,42,FALSE) -> 0 | AY15: =SUM(AU15:AX15) -> 9 | AZ15: =VLOOKUP(C15,Theory!B18:AR84,43,FALSE) -> 10 | BA15: =VLOOKUP(C15,Theory!B18:AS84,44,FALSE) -> 0 | BB15: =VLOOKUP(C15,Theory!B18:AT84,45,FALSE) -> 0 | BC15: =VLOOKUP(C15,Theory!B18:AU84,46,FALSE) -> 0 | BD15: =VLOOKUP(C15,Theory!B18:AV84,47,FALSE) -> 0 | BE15: =VLOOKUP(C15,Theory!B18:AW84,48,FALSE) -> 0 | BF15: =VLOOKUP(C15,Theory!B18:AX84,49,FALSE) -> 0 | BG15: =VLOOKUP(C15,Theory!B18:AY84,50,FALSE) -> 0 | BH15: =MAX(SUM(AZ15:BC15),SUM(BD15:BG15)) -> 10 | BI15: =VLOOKUP(C15,Theory!B18:AZ84,51,FALSE) -> 8 | BJ15: =VLOOKUP(C15,Theory!B18:BA84,52,FALSE) -> 0 | BK15: =VLOOKUP(C15,Theory!B18:BB84,53,FALSE) -> 0 | BL15: =VLOOKUP(C15,Theory!B18:BC84,54,FALSE) -> 0 | BM15: =VLOOKUP(C15,Theory!B18:BD84,55,FALSE) -> 0 | BN15: =VLOOKUP(C15,Theory!B18:BE84,56,FALSE) -> 0 | BO15: =VLOOKUP(C15,Theory!B18:BF84,57,FALSE) -> 0 | BP15: =VLOOKUP(C15,Theory!B18:BG84,58,FALSE) -> 0 | BQ15: =MAX(SUM(BI15:BL15),SUM(BM15:BP15)) -> 8 | BR15: =VLOOKUP(C15,Theory!B18:BH84,59,FALSE) -> 9 | BS15: =VLOOKUP(C15,Theory!B18:BI84,60,FALSE) -> 0 | BT15: =VLOOKUP(C15,Theory!B18:BJ84,61,FALSE) -> 0 | BU15: =VLOOKUP(C15,Theory!B18:BK84,62,FALSE) -> 0 | BV15: =VLOOKUP(C15,Theory!B18:BL84,63,FALSE) -> 0 | BW15: =VLOOKUP(C15,Theory!B18:BM84,64,FALSE) -> 0 | BX15: =VLOOKUP(C15,Theory!B18:BN84,65,FALSE) -> 0 | BY15: =VLOOKUP(C15,Theory!B18:BO84,66,FALSE) -> 0 | BZ15: =MAX(SUM(BR15:BU15),SUM(BV15:BY15)) -> 9 | CA15: =SUM(AT15,AY15,BH15,BQ15,BZ15) -> 45 | CB15: =VLOOKUP(C15,Theory!B18:BP84,67,FALSE) -> 10 | CC15: =VLOOKUP(C15,Theory!B18:BQ84,68,FALSE) -> 0 | CD15: =VLOOKUP(C15,Theory!B18:BR84,69,FALSE) -> 0 | CE15: =VLOOKUP(C15,Theory!B18:BS84,70,FALSE) -> 0 | CF15: =SUM(CB15:CE15) -> 10 | CG15: =VLOOKUP(C15,Theory!B18:BT84,71,FALSE) -> 9 | CH15: =VLOOKUP(C15,Theory!B18:BU84,72,FALSE) -> 0 | CI15: =VLOOKUP(C15,Theory!B18:BV84,73,FALSE) -> 0 | CJ15: =VLOOKUP(C15,Theory!B18:BW84,74,FALSE) -> 0 | CK15: =SUM(CG15:CJ15) -> 9 | CL15: =VLOOKUP(C15,Theory!B18:BX84,75,FALSE) -> 9 | CM15: =VLOOKUP(C15,Theory!B18:BY84,76,FALSE) -> 0 | CN15: =VLOOKUP(C15,Theory!B18:BZ84,77,FALSE) -> 0 | CO15: =VLOOKUP(C15,Theory!B18:CA84,78,FALSE) -> 0 | CP15: =VLOOKUP(C15,Theory!B18:CB84,79,FALSE) -> 0 | CQ15: =VLOOKUP(C15,Theory!B18:CC84,80,FALSE) -> 0 | CR15: =VLOOKUP(C15,Theory!B18:CD84,81,FALSE) -> 0 | CS15: =VLOOKUP(C15,Theory!B18:CE84,82,FALSE) -> 0 | CT15: =MAX(SUM(CL15:CO15),SUM(CP15:CS15)) -> 9 | CU15: =VLOOKUP(C15,Theory!B18:CF84,83,FALSE) -> 10 | CV15: =VLOOKUP(C15,Theory!B18:CG84,84,FALSE) -> 0 | CW15: =VLOOKUP(C15,Theory!B18:CH84,85,FALSE) -> 0 | CX15: =VLOOKUP(C15,Theory!B18:CI84,86,FALSE) -> 0 | CY15: =VLOOKUP(C15,Theory!B18:CJ84,87,FALSE) -> 0 | CZ15: =VLOOKUP(C15,Theory!B18:CK84,88,FALSE) -> 0 | DA15: =VLOOKUP(C15,Theory!B18:CL84,89,FALSE) -> 0 | DB15: =VLOOKUP(C15,Theory!B18:CM84,90,FALSE) -> 0 | DC15: =MAX(SUM(CU15:CX15),SUM(CY15:DB15)) -> 10 | DD15: =VLOOKUP(C15,Theory!B18:CN84,91,FALSE) -> 0 | DE15: =VLOOKUP(C15,Theory!B18:CO84,92,FALSE) -> 0 | DF15: =VLOOKUP(C15,Theory!B18:CP84,93,FALSE) -> 0 | DG15: =VLOOKUP(C15,Theory!B18:CQ84,94,FALSE) -> 0 | DH15: =VLOOKUP(C15,Theory!B18:CR84,95,FALSE) -> 10 | DI15: =VLOOKUP(C15,Theory!B18:CS84,96,FALSE) -> 0 | DJ15: =VLOOKUP(C15,Theory!B18:CT84,97,FALSE) -> 0 | DK15: =VLOOKUP(C15,Theory!B18:CU84,98,FALSE) -> 0 | DL15: =MAX(SUM(DD15:DG15),SUM(DH15:DK15)) -> 10 | DM15: =SUM(CF15,CK15,CT15,DC15,DL15) -> 48 | DN15: =AO15 -> 48 | DO15: =CA15 -> 45 | DP15: =DM15 -> 48 | DQ15: =ROUND(30*DN15/50,0) -> 29 | DR15: =ROUND(30*DO15/50,0) -> 27 | DS15: =ROUND(30*DP15/50,0) -> 29 | DT15: =ROUND(AVERAGE(DQ15:DS15),0) -> 28 | DU15: =VLOOKUP(C15,Theory!B18:CV84,99,FALSE) -> 10 | DV15: =VLOOKUP(C15,Theory!B18:CW84,100,FALSE) -> 10 | DW15: =SUM(DU15:DV15) -> 20 | DX15: =SUM(DT15:DV15) -> 48 | DY15: =ROUND((30*DX15/50),0) -> 29 | DZ15: =VLOOKUP(C15,Lab!B10:D79,3,FALSE) -> 0 | EA15: =VLOOKUP(C15,Lab!B10:E79,4,FALSE) -> 0 | EB15: =VLOOKUP(C15,Lab!B10:F79,5,FALSE) -> 0 | EC15: =SUM(DZ15:EB15) -> 0 | ED15: =VLOOKUP(C15,Lab!B10:G79,6,FALSE) -> 0 | EE15: =VLOOKUP(C15,Lab!B10:H79,7,FALSE) -> 0 | EF15: =VLOOKUP(C15,Lab!B10:I79,8,FALSE) -> 0 | EG15: =SUM(ED15:EF15) -> 0 | EH15: =SUM(EC15,EG15) -> 0 | EI15: =ROUND((20*EH15/50),0) -> 0 | EJ15: =SUM(DY15,EI15) -> 29 | EK15: 40 | EM15: =VLOOKUP(C15,Theory!B18:DL84,114,FALSE) -> 0 | EN15: =VLOOKUP(C15,Theory!B18:DM84,115,FALSE) -> 0 | EO15: =VLOOKUP(C15,Theory!B18:DN84,116,FALSE) -> 0 | EP15: =VLOOKUP(C15,Theory!B18:DO84,117,FALSE) -> 0 | EQ15: =VLOOKUP(C15,Theory!B18:DP84,118,FALSE) -> 0 | ER15: =VLOOKUP(C15,Theory!B18:DQ84,119,FALSE) -> 0 | ES15: =VLOOKUP(C15,Theory!B18:DR84,120,FALSE) -> 0 | ET15: =SUM(ER15:ES15) -> 0
A16: 3 | B16: =Theory!C19 -> ANKUSH G | C16: =Theory!B19 -> 1DS21AI005 | D16: =VLOOKUP(C16,Theory!B19:D85,3,FALSE) -> 7 | E16: =VLOOKUP(C16,Theory!B19:E85,4,FALSE) -> 0 | F16: =VLOOKUP(C16,Theory!B19:F85,5,FALSE) -> 0 | G16: =VLOOKUP(C16,Theory!B19:G85,6,FALSE) -> 0 | H16: =SUM(D16:G16) -> 7 | I16: =VLOOKUP(C16,Theory!B19:H85,7,FALSE) -> 8 | J16: =VLOOKUP(C16,Theory!B19:I85,8,FALSE) -> 0 | K16: =VLOOKUP(C16,Theory!B19:J85,9,FALSE) -> 0 | L16: =VLOOKUP(C16,Theory!B19:K85,10,FALSE) -> 0 | M16: =SUM(I16:L16) -> 8 | N16: =VLOOKUP(C16,Theory!B19:L85,11,FALSE) -> 0 | O16: =VLOOKUP(C16,Theory!B19:M85,12,FALSE) -> 0 | P16: =VLOOKUP(C16,Theory!B19:N85,13,FALSE) -> 0 | Q16: =VLOOKUP(C16,Theory!B19:O85,14,FALSE) -> 0 | R16: =VLOOKUP(C16,Theory!B19:P85,15,FALSE) -> 9 | S16: =VLOOKUP(C16,Theory!B19:Q85,16,FALSE) -> 0 | T16: =VLOOKUP(C16,Theory!B19:R85,17,FALSE) -> 0 | U16: =VLOOKUP(C16,Theory!B19:S85,18,FALSE) -> 0 | V16: =MAX(SUM(N16:Q16),SUM(R16:U16)) -> 9 | W16: =VLOOKUP(C16,Theory!B19:T85,19,FALSE) -> 0 | X16: =VLOOKUP(C16,Theory!B19:U85,20,FALSE) -> 0 | Y16: =VLOOKUP(C16,Theory!B19:V85,21,FALSE) -> 0 | Z16: =VLOOKUP(C16,Theory!B19:W85,22,FALSE) -> 0 | AA16: =VLOOKUP(C16,Theory!B19:X85,23,FALSE) -> 9 | AB16: =VLOOKUP(C16,Theory!B19:Y85,24,FALSE) -> 0 | AC16: =VLOOKUP(C16,Theory!B19:Z85,25,FALSE) -> 0 | AD16: =VLOOKUP(C16,Theory!B19:AA85,26,FALSE) -> 0 | AE16: =MAX(SUM(W16:Z16),SUM(AA16:AD16)) -> 9 | AF16: =VLOOKUP(C16,Theory!B19:AB85,27,FALSE) -> 10 | AG16: =VLOOKUP(C16,Theory!B19:AC85,28,FALSE) -> 0 | AH16: =VLOOKUP(C16,Theory!B19:AD85,29,FALSE) -> 0 | AI16: =VLOOKUP(C16,Theory!B19:AE85,30,FALSE) -> 0 | AJ16: =VLOOKUP(C16,Theory!B19:AF85,31,FALSE) -> 0 | AK16: =VLOOKUP(C16,Theory!B19:AG85,32,FALSE) -> 0 | AL16: =VLOOKUP(C16,Theory!B19:AH85,33,FALSE) -> 0 | AM16: =VLOOKUP(C16,Theory!B19:AI85,34,FALSE) -> 0 | AN16: =MAX(SUM(AF16:AI16),SUM(AJ16:AM16)) -> 10 | AO16: =SUM(H16,M16,V16,AE16,AN16) -> 43 | AP16: =VLOOKUP(C16,Theory!B19:AJ85,35,FALSE) -> 9 | AQ16: =VLOOKUP(C16,Theory!B19:AK85,36,FALSE) -> 0 | AR16: =VLOOKUP(C16,Theory!B19:AL85,37,FALSE) -> 0 | AS16: =VLOOKUP(C16,Theory!B19:AM85,38,FALSE) -> 0 | AT16: =SUM(AP16:AS16) -> 9 | AU16: =VLOOKUP(C16,Theory!B19:AN85,39,FALSE) -> 10 | AV16: =VLOOKUP(C16,Theory!B19:AO85,40,FALSE) -> 0 | AW16: =VLOOKUP(C16,Theory!B19:AP85,41,FALSE) -> 0 | AX16: =VLOOKUP(C16,Theory!B19:AQ85,42,FALSE) -> 0 | AY16: =SUM(AU16:AX16) -> 10 | AZ16: =VLOOKUP(C16,Theory!B19:AR85,43,FALSE) -> 10 | BA16: =VLOOKUP(C16,Theory!B19:AS85,44,FALSE) -> 0 | BB16: =VLOOKUP(C16,Theory!B19:AT85,45,FALSE) -> 0 | BC16: =VLOOKUP(C16,Theory!B19:AU85,46,FALSE) -> 0 | BD16: =VLOOKUP(C16,Theory!B19:AV85,47,FALSE) -> 0 | BE16: =VLOOKUP(C16,Theory!B19:AW85,48,FALSE) -> 0 | BF16: =VLOOKUP(C16,Theory!B19:AX85,49,FALSE) -> 0 | BG16: =VLOOKUP(C16,Theory!B19:AY85,50,FALSE) -> 0 | BH16: =MAX(SUM(AZ16:BC16),SUM(BD16:BG16)) -> 10 | BI16: =VLOOKUP(C16,Theory!B19:AZ85,51,FALSE) -> 8 | BJ16: =VLOOKUP(C16,Theory!B19:BA85,52,FALSE) -> 0 | BK16: =VLOOKUP(C16,Theory!B19:BB85,53,FALSE) -> 0 | BL16: =VLOOKUP(C16,Theory!B19:BC85,54,FALSE) -> 0 | BM16: =VLOOKUP(C16,Theory!B19:BD85,55,FALSE) -> 0 | BN16: =VLOOKUP(C16,Theory!B19:BE85,56,FALSE) -> 0 | BO16: =VLOOKUP(C16,Theory!B19:BF85,57,FALSE) -> 0 | BP16: =VLOOKUP(C16,Theory!B19:BG85,58,FALSE) -> 0 | BQ16: =MAX(SUM(BI16:BL16),SUM(BM16:BP16)) -> 8 | BR16: =VLOOKUP(C16,Theory!B19:BH85,59,FALSE) -> 10 | BS16: =VLOOKUP(C16,Theory!B19:BI85,60,FALSE) -> 0 | BT16: =VLOOKUP(C16,Theory!B19:BJ85,61,FALSE) -> 0 | BU16: =VLOOKUP(C16,Theory!B19:BK85,62,FALSE) -> 0 | BV16: =VLOOKUP(C16,Theory!B19:BL85,63,FALSE) -> 0 | BW16: =VLOOKUP(C16,Theory!B19:BM85,64,FALSE) -> 0 | BX16: =VLOOKUP(C16,Theory!B19:BN85,65,FALSE) -> 0 | BY16: =VLOOKUP(C16,Theory!B19:BO85,66,FALSE) -> 0 | BZ16: =MAX(SUM(BR16:BU16),SUM(BV16:BY16)) -> 10 | CA16: =SUM(AT16,AY16,BH16,BQ16,BZ16) -> 47 | CB16: =VLOOKUP(C16,Theory!B19:BP85,67,FALSE) -> 9 | CC16: =VLOOKUP(C16,Theory!B19:BQ85,68,FALSE) -> 0 | CD16: =VLOOKUP(C16,Theory!B19:BR85,69,FALSE) -> 0 | CE16: =VLOOKUP(C16,Theory!B19:BS85,70,FALSE) -> 0 | CF16: =SUM(CB16:CE16) -> 9 | CG16: =VLOOKUP(C16,Theory!B19:BT85,71,FALSE) -> 9 | CH16: =VLOOKUP(C16,Theory!B19:BU85,72,FALSE) -> 0 | CI16: =VLOOKUP(C16,Theory!B19:BV85,73,FALSE) -> 0 | CJ16: =VLOOKUP(C16,Theory!B19:BW85,74,FALSE) -> 0 | CK16: =SUM(CG16:CJ16) -> 9 | CL16: =VLOOKUP(C16,Theory!B19:BX85,75,FALSE) -> 0 | CM16: =VLOOKUP(C16,Theory!B19:BY85,76,FALSE) -> 0 | CN16: =VLOOKUP(C16,Theory!B19:BZ85,77,FALSE) -> 0 | CO16: =VLOOKUP(C16,Theory!B19:CA85,78,FALSE) -> 0 | CP16: =VLOOKUP(C16,Theory!B19:CB85,79,FALSE) -> 10 | CQ16: =VLOOKUP(C16,Theory!B19:CC85,80,FALSE) -> 0 | CR16: =VLOOKUP(C16,Theory!B19:CD85,81,FALSE) -> 0 | CS16: =VLOOKUP(C16,Theory!B19:CE85,82,FALSE) -> 0 | CT16: =MAX(SUM(CL16:CO16),SUM(CP16:CS16)) -> 10 | CU16: =VLOOKUP(C16,Theory!B19:CF85,83,FALSE) -> 10 | CV16: =VLOOKUP(C16,Theory!B19:CG85,84,FALSE) -> 0 | CW16: =VLOOKUP(C16,Theory!B19:CH85,85,FALSE) -> 0 | CX16: =VLOOKUP(C16,Theory!B19:CI85,86,FALSE) -> 0 | CY16: =VLOOKUP(C16,Theory!B19:CJ85,87,FALSE) -> 0 | CZ16: =VLOOKUP(C16,Theory!B19:CK85,88,FALSE) -> 0 | DA16: =VLOOKUP(C16,Theory!B19:CL85,89,FALSE) -> 0 | DB16: =VLOOKUP(C16,Theory!B19:CM85,90,FALSE) -> 0 | DC16: =MAX(SUM(CU16:CX16),SUM(CY16:DB16)) -> 10 | DD16: =VLOOKUP(C16,Theory!B19:CN85,91,FALSE) -> 9 | DE16: =VLOOKUP(C16,Theory!B19:CO85,92,FALSE) -> 0 | DF16: =VLOOKUP(C16,Theory!B19:CP85,93,FALSE) -> 0 | DG16: =VLOOKUP(C16,Theory!B19:CQ85,94,FALSE) -> 0 | DH16: =VLOOKUP(C16,Theory!B19:CR85,95,FALSE) -> 0 | DI16: =VLOOKUP(C16,Theory!B19:CS85,96,FALSE) -> 0 | DJ16: =VLOOKUP(C16,Theory!B19:CT85,97,FALSE) -> 0 | DK16: =VLOOKUP(C16,Theory!B19:CU85,98,FALSE) -> 0 | DL16: =MAX(SUM(DD16:DG16),SUM(DH16:DK16)) -> 9 | DM16: =SUM(CF16,CK16,CT16,DC16,DL16) -> 47 | DN16: =AO16 -> 43 | DO16: =CA16 -> 47 | DP16: =DM16 -> 47 | DQ16: =ROUND(30*DN16/50,0) -> 26 | DR16: =ROUND(30*DO16/50,0) -> 28 | DS16: =ROUND(30*DP16/50,0) -> 28 | DT16: =ROUND(AVERAGE(DQ16:DS16),0) -> 27 | DU16: =VLOOKUP(C16,Theory!B19:CV85,99,FALSE) -> 10 | DV16: =VLOOKUP(C16,Theory!B19:CW85,100,FALSE) -> 10 | DW16: =SUM(DU16:DV16) -> 20 | DX16: =SUM(DT16:DV16) -> 47 | DY16: =ROUND((30*DX16/50),0) -> 28 | DZ16: =VLOOKUP(C16,Lab!B11:D80,3,FALSE) -> 0 | EA16: =VLOOKUP(C16,Lab!B11:E80,4,FALSE) -> 0 | EB16: =VLOOKUP(C16,Lab!B11:F80,5,FALSE) -> 0 | EC16: =SUM(DZ16:EB16) -> 0 | ED16: =VLOOKUP(C16,Lab!B11:G80,6,FALSE) -> 0 | EE16: =VLOOKUP(C16,Lab!B11:H80,7,FALSE) -> 0 | EF16: =VLOOKUP(C16,Lab!B11:I80,8,FALSE) -> 0 | EG16: =SUM(ED16:EF16) -> 0 | EH16: =SUM(EC16,EG16) -> 0 | EI16: =ROUND((20*EH16/50),0) -> 0 | EJ16: =SUM(DY16,EI16) -> 28 | EK16: 42 | EM16: =VLOOKUP(C16,Theory!B19:DL85,114,FALSE) -> 0 | EN16: =VLOOKUP(C16,Theory!B19:DM85,115,FALSE) -> 0 | EO16: =VLOOKUP(C16,Theory!B19:DN85,116,FALSE) -> 0 | EP16: =VLOOKUP(C16,Theory!B19:DO85,117,FALSE) -> 0 | EQ16: =VLOOKUP(C16,Theory!B19:DP85,118,FALSE) -> 0 | ER16: =VLOOKUP(C16,Theory!B19:DQ85,119,FALSE) -> 0 | ES16: =VLOOKUP(C16,Theory!B19:DR85,120,FALSE) -> 0 | ET16: =SUM(ER16:ES16) -> 0
